Workbook

Sheet Std
A1: Standard
B3: Mexhine / Process | C3: Specification / Tolerance | D3: Product
A4: Raw Material | B4: DRC RM | C4: - | D4: Bokar
A5: Wet Process | B5: Slab Cutter (SC) | C5: maks. 200mm | D5: Cacahan SC
B6: Pre-Breaker (PB) | C6: maks. 150mm | D6: Cacahan PB
B7: Hammer Mill (HM) | C7: maks. 100mm | D7: Cacahan HM
B8: Shredder 1 (SH1) | C8: 5±1mm | D8: Cacahan SH1
B9: Creeper 8 (CP8) | C9: 10±2mm | D9: Blanket Basah
A10: Ampaian | B10: DRC Ampaian | C10: DRC ≥ 90%; < 90%, izin manager/direksi | D10: Blanket Kering
B11: Dirt | C11: maks. 0.16% (SIR20); maks. 0.08% (SIR10) | D11: Blanket Kering
B12: P0 | C12: min. 30 (SIR20); min. 30 (SIR10) | D12: Blanket Kering
B13: PRI | C13: min. 40 (SIR20); min. 50 (SIR10) | D13: Blanket Kering
B14: MV | C14: min. 65 (internal) | D14: Blanket Kering
A15: Dry Process | B15: Shredder 2 (SH2) | C15: 5±1mm | D15: Cacahan SH2
B16: Feeding Station & Trolley | C16: - | D16: Crumb
B17: P0 | C17: min. 30 (SIR20); min. 30 (SIR10) | D17: Cake/Biscuit
B18: PRI | C18: min. 40 (SIR20); min. 50 (SIR10) | D18: Cake/Biscuit | G18: Int (PBS) | I18: SNI 1903 | K18: Belshina | L18: Kamma Tyres | M18: PT GAJAH TUNGGAL, Tbk
B19: MV | C19: min. 65 (internal); Buyer Standard | D19: Cake/Biscuit | G19: SIR10 | H19: SIR20 | I19: SIR10 | J19: SIR20 | K19: SIR20 | L19: SIR20 | M19: SIR20
A20: Laboratory | B20: Dirt | C20: maks. 0.16% (SIR20); maks. 0.08% (SIR10) | D20: Bale/Pallet | F20: Dirt % | G20: 0.08 | H20: 0.13 | I20: 0.08 | J20: 0.16 | K20: 0.16 | L20: 0.20 (Tar 0.15) | M20: 0.16
B21: Ash | C21: maks. 1.00% (SIR20); maks. 0.75% (SIR10) | D21: Bale/Pallet | F21: Ash % | G21: 0.5 | H21: 0.5 | I21: 0.75 | J21: 1 | K21: 0.8 | L21: 1.00 (Tar 0.80) | M21: 1
B22: VM | C22: maks. 0.80% (SIR20); maks. 0.80% (SIR10) | D22: Bale/Pallet | F22: VM % | G22: 0.4 | H22: 0.4 | I22: 0.8 | J22: 0.8 | K22: 0.8 | L22: 0.80 [cp,cpk > 1.33] | M22: 0.8
B23: P0 | C23: min. 30 (SIR20); min. 30 (SIR10) | D23: Bale/Pallet | F23: P0 | G23: 32 | H23: 32 | I23: 30 | J23: 30 | K23: 30 | L23: 30 - 50 mm [cp,cpk > 1.67] | M23: 30
B24: PRI | C24: min. 40 (SIR20); min. 50 (SIR10) | D24: Bale/Pallet | F24: PRI | G24: 65 | H24: 65 | I24: 50 | J24: 40 | K24: 50 | L24: 55 [cp,cpk > 1.67] | M24: 40
B25: N | C25: maks. 0.60% (SIR20); maks. 0.60% (SIR10) | D25: Bale/Pallet | F25: N | G25: 0.25 | H25: 0.25 | I25: 0.6 | J25: 0.6 | K25: 0.6 | L25: 0.6 | M25: 0.6
B26: MV | C26: min. 65 (internal); Buyer Standard | D26: Bale/Pallet | F26: MV | G26: 65 | H26: 65 | I26: - | J26: - | K26: 75-88 (dest) | L26: 73 - 93 (OOO - H3ГШ) | M26: 60
A27: Quality Control | B27: PDI | C27: Kontaminasi, WS, Metal (MP/MS), Jamur, Hasil Uji Lab, Pallet, Packing | D27: Good / Not Good | K27: 70-83 (manuf) | L27: 73 - 88 (ПAO - HKШ)
A28: Finisgood | B28: Alokasi Pengiriman | C28: Produk Good | D28: No Export
A29: Export | B29: Dokumen Export | C29: CoQ, CoQ, TR, and RoA, Sampel (request Buyer) | D29: Dokumen

Sheet Sum
A1: Summary Report
A3: Batch | B3: Raw Material | C3: Wet Process | D3: Ampaian | E3: Dry Process | J3: Laboratory | P3: Quality Control | Q3: Finisgood | R3: Status | S3: Keterangan
E4: Produk Sesuai | F4: Produk Tidak Sesuai | G4: Total Produk | I4: Tanggal Analisa (Terakhir) | J4: Total | K4: P0 > 30 | L4: P0 < 30 | M4: PRI > 65 | N4: PRI < 65 | P4: Total Belum di PDI | Q4: Total Barang Ready
A5: 27 | B5: =SUMIF(RM!B:B,Sum!A5,RM!G:G) -> 34041.867 | C5: =SUMIF(Ampaian!A:A,Sum!A5,Ampaian!G:G) -> 0 | D5: =SUMIF(Ampaian!A:A,Sum!A5,Ampaian!U:U) -> 0 | E5: =SUMIF(Dry!A:A,Sum!A5,Dry!AP:AP) -> 665 | F5: =SUMIF(Dry!A:A,Sum!A5,Dry!AS:AS) -> 3570 | G5: =SUM(E5:F5) -> 4235 | I5: =MAX(Lab!H5:H1048576) -> 46312 | J5: =COUNTIFS(Lab!D5:D1048576,"<0") -> 99 | K5: =COUNTIFS(Lab!N5:N1048576,">30",Lab!D5:D1048576,"<0") -> 97 | L5: =COUNTIFS(Lab!N5:N1048576,"<30",Lab!D5:D1048576,"<0") -> 2 | M5: =COUNTIFS(Lab!P5:P1048576,">65",Lab!D5:D1048576,"<0") -> 97 | N5: =COUNTIFS(Lab!P5:P1048576,"<65",Lab!D5:D1048576,"<0") -> 2
A6: 28 | B6: =SUMIF(RM!B:B,Sum!A6,RM!G:G) -> 39527.682 | C6: =SUMIF(Ampaian!A:A,Sum!A6,Ampaian!G:G) -> 64256.171 | D6: =SUMIF(Ampaian!A:A,Sum!A6,Ampaian!U:U) -> 46913.345 | E6: =SUMIF(Dry!A:A,Sum!A6,Dry!AP:AP) -> 44730 | F6: =SUMIF(Dry!A:A,Sum!A6,Dry!AS:AS) -> 2310 | G6: =SUM(E6:F6) -> 47040
A7: 1 | B7: =SUMIF(RM!B:B,Sum!A7,RM!G:G) -> 34042.634 | C7: =SUMIF(Ampaian!A:A,Sum!A7,Ampaian!G:G) -> 35336.111 | D7: =SUMIF(Ampaian!A:A,Sum!A7,Ampaian!U:U) -> 8247.9251 | E7: =SUMIF(Dry!A:A,Sum!A7,Dry!AP:AP) -> 30380 | F7: =SUMIF(Dry!A:A,Sum!A7,Dry!AS:AS) -> 1190 | G7: =SUM(E7:F7) -> 31570
A8: 2 | B8: =SUMIF(RM!B:B,Sum!A8,RM!G:G) -> 37654.909 | C8: =SUMIF(Ampaian!A:A,Sum!A8,Ampaian!G:G) -> 38562.14 | D8: =SUMIF(Ampaian!A:A,Sum!A8,Ampaian!U:U) -> 12131.808 | E8: =SUMIF(Dry!A:A,Sum!A8,Dry!AP:AP) -> 33040 | F8: =SUMIF(Dry!A:A,Sum!A8,Dry!AS:AS) -> 3220 | G8: =SUM(E8:F8) -> 36260
A9: 3 | B9: =SUMIF(RM!B:B,Sum!A9,RM!G:G) -> 35011.848 | C9: =SUMIF(Ampaian!A:A,Sum!A9,Ampaian!G:G) -> 36619.779 | D9: =SUMIF(Ampaian!A:A,Sum!A9,Ampaian!U:U) -> 2998.4886 | E9: =SUMIF(Dry!A:A,Sum!A9,Dry!AP:AP) -> 29085 | F9: =SUMIF(Dry!A:A,Sum!A9,Dry!AS:AS) -> 1925 | G9: =SUM(E9:F9) -> 31010
A10: 4 | B10: =SUMIF(RM!B:B,Sum!A10,RM!G:G) -> 43045.551 | C10: =SUMIF(Ampaian!A:A,Sum!A10,Ampaian!G:G) -> 39744.929 | D10: =SUMIF(Ampaian!A:A,Sum!A10,Ampaian!U:U) -> 38166.225 | E10: =SUMIF(Dry!A:A,Sum!A10,Dry!AP:AP) -> 34860 | F10: =SUMIF(Dry!A:A,Sum!A10,Dry!AS:AS) -> 1155 | G10: =SUM(E10:F10) -> 36015
A11: 5 | B11: =SUMIF(RM!B:B,Sum!A11,RM!G:G) -> 35483.133 | C11: =SUMIF(Ampaian!A:A,Sum!A11,Ampaian!G:G) -> 40311.511 | D11: =SUMIF(Ampaian!A:A,Sum!A11,Ampaian!U:U) -> 36487.818 | E11: =SUMIF(Dry!A:A,Sum!A11,Dry!AP:AP) -> 28910 | F11: =SUMIF(Dry!A:A,Sum!A11,Dry!AS:AS) -> 8855 | G11: =SUM(E11:F11) -> 37765
A12: 6 | B12: =SUMIF(RM!B:B,Sum!A12,RM!G:G) -> 36470.12 | C12: =SUMIF(Ampaian!A:A,Sum!A12,Ampaian!G:G) -> 37310.303 | D12: =SUMIF(Ampaian!A:A,Sum!A12,Ampaian!U:U) -> 36239.725 | E12: =SUMIF(Dry!A:A,Sum!A12,Dry!AP:AP) -> 30660 | F12: =SUMIF(Dry!A:A,Sum!A12,Dry!AS:AS) -> 7350 | G12: =SUM(E12:F12) -> 38010
A13: 7 | B13: =SUMIF(RM!B:B,Sum!A13,RM!G:G) -> 36097.966 | C13: =SUMIF(Ampaian!A:A,Sum!A13,Ampaian!G:G) -> 37596.615 | D13: =SUMIF(Ampaian!A:A,Sum!A13,Ampaian!U:U) -> 36507.48 | E13: =SUMIF(Dry!A:A,Sum!A13,Dry!AP:AP) -> 44135 | F13: =SUMIF(Dry!A:A,Sum!A13,Dry!AS:AS) -> 700 | G13: =SUM(E13:F13) -> 44835
A14: 8 | B14: =SUMIF(RM!B:B,Sum!A14,RM!G:G) -> 53986.293 | C14: =SUMIF(Ampaian!A:A,Sum!A14,Ampaian!G:G) -> 59467.974 | D14: =SUMIF(Ampaian!A:A,Sum!A14,Ampaian!U:U) -> 54243.343 | E14: =SUMIF(Dry!A:A,Sum!A14,Dry!AP:AP) -> 0 | F14: =SUMIF(Dry!A:A,Sum!A14,Dry!AS:AS) -> 0 | G14: =SUM(E14:F14) -> 0
A15: 9 | B15: =SUMIF(RM!B:B,Sum!A15,RM!G:G) -> 35058.466 | C15: =SUMIF(Ampaian!A:A,Sum!A15,Ampaian!G:G) -> 37109.45 | D15: =SUMIF(Ampaian!A:A,Sum!A15,Ampaian!U:U) -> 34611.984 | E15: =SUMIF(Dry!A:A,Sum!A15,Dry!AP:AP) -> 33425 | F15: =SUMIF(Dry!A:A,Sum!A15,Dry!AS:AS) -> 1960 | G15: =SUM(E15:F15) -> 35385
A16: 10 | B16: =SUMIF(RM!B:B,Sum!A16,RM!G:G) -> 33749.763 | C16: =SUMIF(Ampaian!A:A,Sum!A16,Ampaian!G:G) -> 34008.712 | D16: =SUMIF(Ampaian!A:A,Sum!A16,Ampaian!U:U) -> 31278.676 | E16: =SUMIF(Dry!A:A,Sum!A16,Dry!AP:AP) -> 0 | F16: =SUMIF(Dry!A:A,Sum!A16,Dry!AS:AS) -> 0 | G16: =SUM(E16:F16) -> 0
A17: 11 | B17: =SUMIF(RM!B:B,Sum!A17,RM!G:G) -> 142040 | C17: =SUMIF(Ampaian!A:A,Sum!A17,Ampaian!G:G) -> 150974.81 | D17: =SUMIF(Ampaian!A:A,Sum!A17,Ampaian!U:U) -> 134226.95 | E17: =SUMIF(Dry!A:A,Sum!A17,Dry!AP:AP) -> 57120 | F17: =SUMIF(Dry!A:A,Sum!A17,Dry!AS:AS) -> 6265 | G17: =SUM(E17:F17) -> 63385
A18: 12 | B18: =SUMIF(RM!B:B,Sum!A18,RM!G:G) -> 48860.725 | C18: =SUMIF(Ampaian!A:A,Sum!A18,Ampaian!G:G) -> 51251.541 | D18: =SUMIF(Ampaian!A:A,Sum!A18,Ampaian!U:U) -> 44656.503 | E18: =SUMIF(Dry!A:A,Sum!A18,Dry!AP:AP) -> 43085 | F18: =SUMIF(Dry!A:A,Sum!A18,Dry!AS:AS) -> 7315 | G18: =SUM(E18:F18) -> 50400
A19: 13/14 | B19: =SUMIF(RM!B:B,Sum!A19,RM!G:G) -> 129416.26 | C19: =SUMIF(Ampaian!A:A,Sum!A19,Ampaian!G:G) -> 0 | D19: =SUMIF(Ampaian!A:A,Sum!A19,Ampaian!U:U) -> 0 | E19: =SUMIF(Dry!A:A,Sum!A19,Dry!AP:AP) -> 0 | F19: =SUMIF(Dry!A:A,Sum!A19,Dry!AS:AS) -> 0 | G19: =SUM(E19:F19) -> 0
A20: 15 | B20: =SUMIF(RM!B:B,Sum!A20,RM!G:G) -> 106294 | C20: =SUMIF(Ampaian!A:A,Sum!A20,Ampaian!G:G) -> 0 | D20: =SUMIF(Ampaian!A:A,Sum!A20,Ampaian!U:U) -> 0 | E20: =SUMIF(Dry!A:A,Sum!A20,Dry!AP:AP) -> 0 | F20: =SUMIF(Dry!A:A,Sum!A20,Dry!AS:AS) -> 0 | G20: =SUM(E20:F20) -> 0
B21: =SUMIF(RM!B:B,Sum!A21,RM!G:G) -> 0 | C21: =SUMIF(Ampaian!A:A,Sum!A21,Ampaian!G:G) -> 0 | D21: =SUMIF(Ampaian!A:A,Sum!A21,Ampaian!U:U) -> 0 | E21: =SUMIF(Dry!A:A,Sum!A21,Dry!AP:AP) -> 0 | F21: =SUMIF(Dry!A:A,Sum!A21,Dry!AS:AS) -> 0 | G21: =SUM(E21:F21) -> 0

Sheet RM
B1: Batch | C1: Date of Buy RM | D1: Row Labels (Location) | E1: Volume/Gross (Kg) | F1: Avg of DRC RM (%) | G1: Sum of Net (Kg) | H1: Persentase (%)
B2: 27 | C2: 19 Nov - 10 Des 2025 | D2: ACEH BARAT | E2: =G2/F2*100 -> 35728.048 | F2: 53.850475 | G2: 19239.724 | H2: 0.56517828
B3: 27 | C3: 19 Nov - 10 Des 2025 | D3: ACEH JAYA | E3: =G3/F3*100 -> 19043.21 | F3: 53.436842 | G3: 10176.09 | H3: 0.29892868
B4: 27 | C4: 19 Nov - 10 Des 2025 | D4: NAGAN RAYA | E4: =G4/F4*100 -> 7828.0358 | F4: 59.095957 | G4: 4626.0527 | H4: 0.13589304
B5: 28 | C5: 12 - 31 Des 2025 | D5: ACEH BESAR | E5: =G5/F5*100 -> 820 | F5: 53.743248 | G5: 440.69463 | H5: 0.0070391764
B6: 28 | C6: 12 - 31 Des 2025 | D6: ACEH JAYA | E6: =G6/F6*100 -> 31197.987 | F6: 53.923385 | G6: 16823.011 | H6: 0.26871246
B7: 28 | C7: 12 - 31 Des 2025 | D7: BIREUEN | E7: =G7/F7*100 -> 33684.854 | F7: 63.998226 | G7: 21557.709 | H7: 0.34433938
B8: 28 | C8: 12 - 31 Des 2025 | D8: NAGAN RAYA | E8: =G8/F8*100 -> 1210 | F8: 58.369285 | G8: 706.26835 | H8: 0.011281162
B9: 1 | C9: 02 - 07 Jan 2026 | D9: ACEH BARAT | E9: =G9/F9*100 -> 28644.143 | F9: 54.069623 | G9: 15487.78 | H9: 0.45495246
B10: 1 | C10: 02 - 07 Jan 2026 | D10: BIREUEN | E10: =G10/F10*100 -> 17139.438 | F10: 58.966172 | G10: 10106.471 | H10: 0.29687687
B11: 1 | C11: 02 - 07 Jan 2026 | D11: ACEH JAYA | E11: =G11/F11*100 -> 10826.603 | F11: 54.818837 | G11: 5935.0179 | H11: 0.17434074
B12: 1 | C12: 02 - 07 Jan 2026 | D12: BANDA ACEH | E12: =G12/F12*100 -> 2460 | F12: 62.799763 | G12: 1544.8742 | H12: 0.045380571
B13: 1 | C13: 02 - 07 Jan 2026 | D13: NAGAN RAYA | E13: =G13/F13*100 -> 1630 | F13: 59.416658 | G13: 968.49152 | H13: 0.028449371
... B23: 3 | C23: 19 - 23 Jan 2026 | D23: NAGAN RAYA | E23: =G23/F23*100 -> 1670 | F23: 58.944703 | G23: 984.37654 | H23: 0.028115527
A24: Produksi di Wet batch 5 dahulu baru batch 4 | B24: 4 | C24: 23 - 30 Jan 2026 | D24: ACEH BARAT | E24: =G24/F24*100 -> 28953.475 | F24: 53.604587 | G24: 15520.391 | H24: 0.36055738
B25: 4 | C25: 23 - 30 Jan 2026 | D25: BIREUEN | E25: =G25/F25*100 -> 17110.551 | F25: 61.88744 | G25: 10589.282 | H25: 0.24600178
B26: 4 | C26: 23 - 30 Jan 2026 | D26: ACEH JAYA | E26: =G26/F26*100 -> 19101.579 | F26: 54.070865 | G26: 10328.389 | H26: 0.23994091
B27: 4 | C27: 23 - 30 Jan 2026 | D27: ACEH TENGGARA | E27: =G27/F27*100 -> 5610 | F27: 61.496225 | G27: 3449.9382 | H27: 0.080146221
B28: 4 | C28: 23 - 30 Jan 2026 | D28: NAGAN RAYA | E28: =G28/F28*100 -> 2728.333 | F28: 58.157172 | G28: 1586.7213 | H28: 0.036861448
B29: 4 | C29: 23 - 30 Jan 2026 | D29: BANDA ACEH | E29: =G29/F29*100 -> 2560 | F29: 61.360526 | G29: 1570.8295 | H29: 0.036492261
A30: Produksi di Wet batch 5 dahulu baru batch 4 | B30: 5 | C30: 02 - 05 Feb 2026 | D30: ACEH BARAT | E30: =G30/F30*100 -> 37445.071 | F30: 54.642139 | G30: 20460.788 | H30: 0.57663419
B31: 5 | C31: 02 - 05 Feb 2026 | D31: ACEH JAYA | E31: =G31/F31*100 -> 13160.749 | F31: 54.317824 | G31: 7148.6325 | H31: 0.20146565
B32: 5 | C32: 02 - 05 Feb 2026 | D32: BIREUEN | E32: =G32/F32*100 -> 7800 | F32: 62.57586 | G32: 4880.9171 | H32: 0.13755598
B33: 5 | C33: 02 - 05 Feb 2026 | D33: NAGAN RAYA | E33: =G33/F33*100 -> 5118.9598 | F33: 58.464922 | G33: 2992.7959 | H33: 0.084344184
B34: 6 | C34: 06 - 11 Feb 2026 | D34: ACEH BARAT | E34: =G34/F34*100 -> 38596.894 | F34: 53.615965 | G34: 20694.097 | H34: 0.56742607
B35: 6 | C35: 06 - 11 Feb 2026 | D35: ACEH JAYA | E35: =G35/F35*100 -> 10932.298 | F35: 54.454441 | G35: 5953.1218 | H35: 0.16323285
B36: 6 | C36: 06 - 11 Feb 2026 | D36: BANDA ACEH | E36: =G36/F36*100 -> 2447.7779 | F36: 55.212501 | G36: 1351.4794 | H36: 0.037057169
B37: 6 | C37: 06 - 11 Feb 2026 | D37: BIREUEN | E37: =G37/F37*100 -> 7550 | F37: 60.620364 | G37: 4576.8375 | H37: 0.12549554
B38: 6 | C38: 06 - 11 Feb 2026 | D38: NAGAN RAYA | E38: =G38/F38*100 -> 6738.5542 | F38: 57.79555 | G38: 3894.5845 | H38: 0.10678836
B39: 7 | C39: 11 - 16 Feb 2026 | D39: ACEH BARAT | E39: =G39/F39*100 -> 42949.165 | F39: 53.786618 | G39: 23100.904 | H39: 0.63995028
B40: 7 | C40: 11 - 16 Feb 2026 | D40: ACEH JAYA | E40: =G40/F40*100 -> 12521.657 | F40: 55.707542 | G40: 6975.5073 | H40: 0.19323824
B41: 7 | C41: 11 - 16 Feb 2026 | D41: BIREUEN | E41: =G41/F41*100 -> 7580 | F41: 61.692485 | G41: 4676.2903 | H41: 0.12954443
B42: 7 | C42: 11 - 16 Feb 2026 | D42: NAGAN RAYA | E42: =G42/F42*100 -> 2350.1228 | F42: 57.242319 | G42: 1345.2648 | H42: 0.037267052
... B64: 12 | C64: 19 Jun - 06 Jul 2026 | D64: NAGAN RAYA | E64: =G64/F64*100 -> 10547.42 | F64: 58.890104 | G64: 6211.3866 | H64: 0.12712432
A65: Terdeteksi Metal Pada Prosess Wet, dikarenakan bale Metal telah dicampur pada Batch 13 sebanyak 5642 kgs | B65: 13/14 | C65: 06 Jul - 10 Aug 2026 | D65: ACEH BARAT | E65: =G65/F65*100 -> 124186.78 | F65: 53.136895 | G65: 65989 | H65: 0.64772644
B66: 13/14 | C66: 06 Jul - 10 Aug 2026 | D66: ACEH BESAR | E66: =G66/F66*100 -> 2830.1063 | F66: 61.552459 | G66: 1742 | H66: 0.017098366
B67: 13/14 | C67: 06 Jul - 10 Aug 2026 | D67: ACEH JAYA | E67: =G67/F67*100 -> 42756.984 | F67: 54.236753 | G67: 23190 | H67: 0.22763082
B68: 13/14 | C68: 06 Jul - 10 Aug 2026 | D68: ACEH JAYA/ACEH BARAT | E68: =G68/F68*100 -> 5130.6343 | F68: 55.607159 | G68: 2853 | H68: 0.028000825
B69: 13/14 | C69: 06 Jul - 10 Aug 2026 | D69: NAGAN RAYA | E69: =G69/F69*100 -> 14437.981 | F69: 56.129731 | G69: 8104 | H69: 0.079543548
B70: 13/14 | C70: 11 Aug - 18 Aug 2026 | D70: ACEH BARAT | E70: =G70/F70*100 -> 20866.642 | F70: 51.97986 | G70: 10846.451 | H70: 0.39386841
...

Sheet Wet
A1: Batch | B1: Tanggal Proses Wet | C1: Proses Ke- | D1: SIR | E1: SC | F1: PB | G1: HM | H1: SH.1 | I1: CP8 | J1: Kontaminasi 1 | K1: Kontaminasi 2
A2: 28 | B2: 46011 | C2: 1 | D2: 20 | E2: 141.89 | F2: 97.58 | G2: 42.91 | H2: 18.71 | I2: 15.5 | J2: 548.9 | P2: Standart Ketebalan Cacahan Mesin (mm)
A3: 28 | B3: 46013 | C3: 2 | D3: 20 | E3: 148.03 | F3: 91.21 | G3: 44.34 | H3: 15.9 | I3: 14.1 | P3: SC (Maks 200 mm) | R3: PB (Maks 150 mm) | T3: HM (Maks 100 mm) | V3: SH.1 (5 ± 1 mm) | X3: CP8 (10 ± 2 mm)
A4: 28 | B4: 46020 | C4: 3 | D4: 20 | E4: 105.75 | F4: 91.02 | G4: 28.46 | H4: 13.46 | I4: 15.49 | P4: Min-SC | Q4: Max-SC | R4: Min-PB | S4: Max-PB | T4: Min-HM | U4: Max-HM | V4: Min-SH.1 | W4: Max-SH.1 | X4: Min-CP8 | Y4: Max-CP8
A5: 28 | B5: 46022 | C5: 4 | D5: 20 | E5: 109.61 | F5: 111.44 | G5: 35.33 | H5: 17.95 | I5: 14.68 | P5: 100 | Q5: 200 | R5: 40 | S5: 150 | T5: 20 | U5: 100 | V5: 4 | W5: 6 | X5: 8 | Y5: 12
A6: 28 | B6: 46024 | C6: 5 | D6: 20 | E6: 124.57 | F6: 103.47 | G6: 38.06 | H6: 20.91 | I6: 15.38 | P6: 100 | Q6: 200 | R6: 40 | S6: 150 | T6: 20 | U6: 100 | V6: 4 | W6: 6 | X6: 8 | Y6: 12
A7: 28 | B7: 46025 | C7: 6 | D7: 20 | E7: 119 | F7: 92.67 | G7: 61.09 | H7: 19.27 | I7: 13.45 | P7: 100 | Q7: 200 | R7: 40 | S7: 150 | T7: 20 | U7: 100 | V7: 4 | W7: 6 | X7: 8 | Y7: 12
A8: 1 | B8: 46042 | C8: 7 | D8: 20 | E8: 133.26 | F8: 78.83 | G8: 36.72 | H8: 18.94 | I8: 14.9 | J8: 6.673 | P8: 100 | Q8: 200 | R8: 40 | S8: 150 | T8: 20 | U8: 100 | V8: 4 | W8: 6 | X8: 8 | Y8: 12
A9: 1 | B9: 46043 | C9: 8 | D9: 20 | E9: 138.38 | F9: 73.29 | G9: 40.21 | H9: 16.27 | I9: 16.4 | P9: 100 | Q9: 200 | R9: 40 | S9: 150 | T9: 20 | U9: 100 | V9: 4 | W9: 6 | X9: 8 | Y9: 12
A10: 1 | B10: 46044 | C10: 9 | D10: 20 | E10: 116.16 | F10: 90.27 | G10: 37.4 | H10: 20.5 | I10: 14.69 | P10: 100 | Q10: 200 | R10: 40 | S10: 150 | T10: 20 | U10: 100 | V10: 4 | W10: 6 | X10: 8 | Y10: 12
A11: 2 | B11: 46045 | C11: 10 | D11: 20 | E11: 154.95 | F11: 97.85 | G11: 41.38 | H11: 18.23 | I11: 14.65 | J11: 7.726 | P11: 100 | Q11: 200 | R11: 40 | S11: 150 | T11: 20 | U11: 100 | V11: 4 | W11: 6 | X11: 8 | Y11: 12
A12: 2 | B12: 46046 | C12: 11 | D12: 20 | E12: 113.19 | F12: 89.69 | G12: 53.04 | H12: 18 | I12: 14.8 | P12: 100 | Q12: 200 | R12: 40 | S12: 150 | T12: 20 | U12: 100 | V12: 4 | W12: 6 | X12: 8 | Y12: 12
A13: 2 | B13: 46048 | C13: 12 | D13: 20 | E13: 152.57 | F13: 92.63 | G13: 42.22 | H13: 17.53 | I13: 13.48 | P13: 100 | Q13: 200 | R13: 40 | S13: 150 | T13: 20 | U13: 100 | V13: 4 | W13: 6 | X13: 8 | Y13: 12
A14: 3 | B14: 46049 | C14: 13 | D14: 20 | E14: 147.26 | F14: 97.46 | G14: 51.92 | H14: 29.75 | I14: 14.2 | J14: 10.471 | P14: 100 | Q14: 200 | R14: 40 | S14: 150 | T14: 20 | U14: 100 | V14: 4 | W14: 6 | X14: 8 | Y14: 12
A15: 3 | B15: 46050 | C15: 14 | D15: 20 | E15: 132.36 | F15: 89.25 | G15: 47.19 | H15: 21.59 | I15: 12.98 | P15: 100 | Q15: 200 | R15: 40 | S15: 150 | T15: 20 | U15: 100 | V15: 4 | W15: 6 | X15: 8 | Y15: 12
A16: 5 | B16: 46072 | C16: 15 | D16: 20 | E16: 144.9 | F16: 90.92 | G16: 48.21 | H16: 31.37 | I16: 19.97 | J16: 3.189 | P16: 100 | Q16: 200 | R16: 40 | S16: 150 | T16: 20 | U16: 100 | V16: 4 | W16: 6 | X16: 8 | Y16: 12
A17: 5 | B17: 46076 | C17: 16 | D17: 20 | E17: 152.31 | F17: 89.58 | G17: 57.13 | H17: 20.76 | I17: 17.66 | P17: 100 | Q17: 200 | R17: 40 | S17: 150 | T17: 20 | U17: 100 | V17: 4 | W17: 6 | X17: 8 | Y17: 12
A18: 5 | B18: 46077 | C18: 17 | D18: 20 | E18: 157.95 | F18: 97.36 | G18: 46.69 | H18: 20.7 | I18: 19.2 | P18: 100 | Q18: 200 | R18: 40 | S18: 150 | T18: 20 | U18: 100 | V18: 4 | W18: 6 | X18: 8 | Y18: 12
A19: 5 | B19: 46078 | C19: 18 | D19: 20 | E19: 157.68 | F19: 81.18 | G19: 70.86 | H19: 20.61 | I19: 18.42 | P19: 100 | Q19: 200 | R19: 40 | S19: 150 | T19: 20 | U19: 100 | V19: 4 | W19: 6 | X19: 8 | Y19: 12
A20: 5 | B20: 46079 | C20: 19 | D20: 20 | E20: 164.06 | F20: 90.49 | G20: 42.05 | H20: 29.86 | I20: 20.2 | P20: 100 | Q20: 200 | R20: 40 | S20: 150 | T20: 20 | U20: 100 | V20: 4 | W20: 6 | X20: 8 | Y20: 12
A21: 4 | B21: 46080 | C21: 20 | D21: 20 | E21: 161.51 | F21: 75.09 | G21: 50.14 | H21: 22.59 | I21: 19.46 | J21: 4.7322 | P21: 100 | Q21: 200 | R21: 40 | S21: 150 | T21: 20 | U21: 100 | V21: 4 | W21: 6 | X21: 8 | Y21: 12
A22: 4 | B22: 46081 | C22: 21 | D22: 20 | E22: 171.71 | F22: 96.14 | G22: 42.91 | H22: 28.34 | I22: 18.59 | P22: 100 | Q22: 200 | R22: 40 | S22: 150 | T22: 20 | U22: 100 | V22: 4 | W22: 6 | X22: 8 | Y22: 12
A23: 4 | B23: 46083 | C23: 22 | D23: 20 | E23: 143.71 | F23: 72.3 | G23: 57.59 | H23: 18.26 | I23: 17.74 | P23: 100 | Q23: 200 | R23: 40 | S23: 150 | T23: 20 | U23: 100 | V23: 4 | W23: 6 | X23: 8 | Y23: 12
A24: 4 | B24: 46084 | C24: 23 | D24: 20 | E24: 164.26 | F24: 77.52 | G24: 36.56 | H24: 21.89 | I24: 18.28 | P24: 100 | Q24: 200 | R24: 40 | S24: 150 | T24: 20 | U24: 100 | V24: 4 | W24: 6 | X24: 8 | Y24: 12
A25: 4 | B25: 46085 | C25: 24 | D25: 20 | E25: 159.88 | F25: 79.47 | G25: 46.02 | H25: 19.64 | I25: 17.84 | P25: 100 | Q25: 200 | R25: 40 | S25: 150 | T25: 20 | U25: 100 | V25: 4 | W25: 6 | X25: 8 | Y25: 12
A26: 6 | B26: 46086 | C26: 25 | D26: 20 | E26: 150.21 | F26: 84.69 | G26: 51.2 | H26: 16.65 | I26: 16.7 | J26: 4.942 | P26: 100 | Q26: 200 | R26: 40 | S26: 150 | T26: 20 | U26: 100 | V26: 4 | W26: 6 | X26: 8 | Y26: 12
A27: 6 | B27: 46087 | C27: 26 | D27: 20 | E27: 143.25 | F27: 96.11 | G27: 52.26 | H27: 13.75 | I27: 19.17 | P27: 100 | Q27: 200 | R27: 40 | S27: 150 | T27: 20 | U27: 100 | V27: 4 | W27: 6 | X27: 8 | Y27: 12
A28: 6 | B28: 46090 | C28: 27 | D28: 20 | E28: 122.84 | F28: 84.57 | G28: 46.43 | H28: 15.65 | I28: 15.57 | P28: 100 | Q28: 200 | R28: 40 | S28: 150 | T28: 20 | U28: 100 | V28: 4 | W28: 6 | X28: 8 | Y28: 12
A29: 6 | B29: 46091 | C29: 28 | D29: 20 | E29: 138.4 | F29: 54.11 | G29: 38.58 | H29: 32.03 | I29: 32.77 | P29: 100 | Q29: 200 | R29: 40 | S29: 150 | T29: 20 | U29: 100 | V29: 4 | W29: 6 | X29: 8 | Y29: 12
A30: 7 | B30: 46091 | C30: 29 | D30: 20 | E30: 138.4 | F30: 54.11 | G30: 38.58 | H30: 32.03 | I30: 32.77 | J30: 5.519 | P30: 100 | Q30: 200 | R30: 40 | S30: 150 | T30: 20 | U30: 100 | V30: 4 | W30: 6 | X30: 8 | Y30: 12
A31: 7 | B31: 46092 | C31: 30 | D31: 20 | E31: 129.6 | F31: 88 | G31: 45.9 | H31: 16.43 | I31: 16.63 | P31: 100 | Q31: 200 | R31: 40 | S31: 150 | T31: 20 | U31: 100 | V31: 4 | W31: 6 | X31: 8 | Y31: 12
A32: 7 | B32: 46093 | C32: 31 | D32: 20 | E32: 145.94 | F32: 72.9 | G32: 39.98 | H32: 14.71 | I32: 17.67 | P32: 100 | Q32: 200 | R32: 40 | S32: 150 | T32: 20 | U32: 100 | V32: 4 | W32: 6 | X32: 8 | Y32: 12
A33: 7 | B33: 46094 | C33: 32 | D33: 20 | E33: 130.2 | F33: 78.11 | G33: 47.38 | H33: 16.62 | I33: 17.83 | P33: 100 | Q33: 200 | R33: 40 | S33: 150 | T33: 20 | U33: 100 | V33: 4 | W33: 6 | X33: 8 | Y33: 12
A34: 7 | B34: 46095 | C34: 33 | D34: 20 | E34: 143.8 | F34: 93.55 | G34: 41.95 | H34: 19.92 | I34: 16.18 | P34: 100 | Q34: 200 | R34: 40 | S34: 150 | T34: 20 | U34: 100 | V34: 4 | W34: 6 | X34: 8 | Y34: 12
A35: 8 | B35: 46113 | C35: 34 | D35: 20 | E35: 135.16 | F35: 89.63 | G35: 37.26 | H35: 11.16 | I35: 14.51 | J35: 5.66 | P35: 100 | Q35: 200 | R35: 40 | S35: 150 | T35: 20 | U35: 100 | V35: 4 | W35: 6 | X35: 8 | Y35: 12
A36: 8 | B36: 46114 | C36: 35 | D36: 20 | E36: 103.05 | F36: 94.57 | G36: 50.14 | H36: 10.6 | I36: 15.61 | P36: 100 | Q36: 200 | R36: 40 | S36: 150 | T36: 20 | U36: 100 | V36: 4 | W36: 6 | X36: 8 | Y36: 12
A37: 8 | B37: 46116 | C37: 36 | D37: 20 | E37: 141.93 | F37: 78.12 | G37: 45.68 | H37: 19 | I37: 13.31 | P37: 100 | Q37: 200 | R37: 40 | S37: 150 | T37: 20 | U37: 100 | V37: 4 | W37: 6 | X37: 8 | Y37: 12
A38: 8 | B38: 46118 | C38: 37 | D38: 20 | E38: 125.8 | F38: 76.28 | G38: 41.81 | H38: 10.45 | I38: 14.6 | P38: 100 | Q38: 200 | R38: 40 | S38: 150 | T38: 20 | U38: 100 | V38: 4 | W38: 6 | X38: 8 | Y38: 12
A39: 8 | B39: 46119 | C39: 38 | D39: 20 | E39: 139.42 | F39: 70.29 | G39: 42.41 | H39: 12.17 | I39: 14.78 | P39: 100 | Q39: 200 | R39: 40 | S39: 150 | T39: 20 | U39: 100 | V39: 4 | W39: 6 | X39: 8 | Y39: 12
A40: 8 | B40: 46120 | C40: 39 | D40: 20 | E40: 146.04 | F40: 76.78 | G40: 41.22 | H40: 10.73 | I40: 17.21 | P40: 100 | Q40: 200 | R40: 40 | S40: 150 | T40: 20 | U40: 100 | V40: 4 | W40: 6 | X40: 8 | Y40: 12
...

Sheet Ampaian
A1: Batch | B1: Process ke-n | C1: Grade | D1: Date of Wet Process | E1: Volume/Gross (Kg) | F1: DRC BB (%) | G1: Volume/Net (Kg) | H1: Dirt (%) | I1: Lantai | J1: Block | K1: Kamar | L1: Analysis Date (Day-n) | M1: Total Days | N1: DRC BK (%) | O1: P0 | P1: P30 | Q1: PRI | R1: Dirt (%) | S1: MV | T1: Volume/Gross (Kg) | U1: Volume/Net (Kg)
A2: 28 | B2: 1 | C2: SIR 20 | D2: 46011 | E2: 23708 | F2: 68.643333 | G2: =E2*F2/100 -> 16273.961 | H2: 0.11966667 | I2: 1 | J2: 7 | K2: D,E | L2: 46092 | M2: =L2-D2 -> 81 | N2: 98.226667 | O2: 38.666667 | P2: 31 | Q2: 80.333333 | R2: 0.10433333 | T2: =G2 -> 16273.961 | U2: =T2*N2/100 -> 15985.37
A3: 28 | B3: 2 | C3: SIR 20 | D3: 46013 | E3: 18402 | F3: 76.046667 | G3: =E3*F3/100 -> 13994.108 | H3: 0.10333333 | I3: 1 | J3: 6;5,6 | K3: C,D,E | L3: 46051 | M3: =L3-D3 -> 38 | N3: 95.196667 | O3: 37.333333 | P3: 28.333333 | Q3: 75.666667 | R3: 0.12 | S3: 70.683333 | T3: =G3 -> 13994.108 | U3: =T3*N3/100 -> 13321.924
A4: 28 | B4: 3 | C4: SIR 20 | D4: 46020 | E4: 23481 | F4: 65.54 | G4: =E4*F4/100 -> 15389.447 | H4: 0.117 | I4: 1;2 | J4: 4;1 | K4: D,C;D | L4: 46052 | M4: =L4-D4 -> 32 | N4: 93.706667 | O4: 31.333333 | P4: 22.666667 | Q4: 72.333333 | R4: 0.12133333 | S4: 63 | T4: =G4 -> 15389.447 | U4: =T4*N4/100 -> 14420.938
A5: 28 | B5: 4 | C5: SIR 20 | D5: 46022 | E5: 5274 | F5: 64.49 | G5: =E5*F5/100 -> 3401.2026 | H5: 0.11866667 | I5: 2 | J5: 1 | K5: A | L5: 46053 | M5: =L5-D5 -> 31 | N5: 93.646667 | O5: 39 | P5: 29.666667 | Q5: 76 | R5: 0.122 | S5: 72.833333 | T5: =G5 -> 3401.2026 | U5: =T5*N5/100 -> 3185.1129
A6: 28 | B6: 5 | C6: SIR 20 | D6: 46024 | E6: 15626 | F6: 67.773333 | G6: =E6*F6/100 -> 10590.261 | H6: 0.109 | I6: 2 | J6: 2;3 | K6: A,B;A | L6: 46158 | M6: =L6-D6 -> 134 | T6: =G6 -> 10590.261 | U6: =T6*N6/100 -> 0
A7: 28 | B7: 6 | C7: SIR 20 | D7: 46025 | E7: 6956 | F7: 66.233333 | G7: =E7*F7/100 -> 4607.1907 | H7: 0.12166667 | I7: 3 | J7: 2 | K7: B | L7: 46158 | M7: =L7-D7 -> 133 | T7: =G7 -> 4607.1907 | U7: =T7*N7/100 -> 0
A8: 1 | B8: 7 | C8: SIR 20 | D8: 46042 | E8: 12272 | F8: 67.913333 | G8: =E8*F8/100 -> 8334.3243 | H8: 0.11266667 | I8: 1 | J8: 2 | K8: D,E,C | L8: 46193 | M8: =L8-D8 -> 151 | N8: 98.963333 | O8: 34.666667 | P8: 22 | Q8: 63.466667 | S8: 70.333333 | T8: =G8 -> 8334.3243 | U8: =T8*N8/100 -> 8247.9251
A9: 1 | B9: 8 | C9: SIR 20 | D9: 46043 | E9: 18302 | F9: 70.156667 | G9: =E9*F9/100 -> 12840.073 | H9: 0.10866667 | I9: 1 | J9: 2;1;1 | K9: C;E,D;C | L9: 46158 | M9: =L9-D9 -> 115 | T9: =G9 -> 12840.073 | U9: =T9*N9/100 -> 0
A10: 1 | B10: 9 | C10: SIR 20 | D10: 46044 | E10: 20668 | F10: 68.52 | G10: =E10*F10/100 -> 14161.714 | H10: 0.12033333 | I10: 1 | J10: 1;2-6 | K10: A,B;A | L10: 46158 | M10: =L10-D10 -> 114 | T10: =G10 -> 14161.714 | U10: =T10*N10/100 -> 0
A11: 2 | B11: 10 | C11: SIR 20 | D11: 46045 | E11: 17052 | F11: 71.903333 | G11: =E11*F11/100 -> 12260.956 | H11: 0.11433333 | I11: 1 | J11: 8-10 | K11: A | L11: 46193 | M11: =L11-D11 -> 148 | N11: 98.946667 | O11: 34.666667 | P11: 22 | Q11: 63.433333 | S11: 71.166667 | T11: =G11 -> 12260.956 | U11: =T11*N11/100 -> 12131.808
A12: 2 | B12: 11 | C12: SIR 20 | D12: 46046 | E12: 17006 | F12: 71.943333 | G12: =E12*F12/100 -> 12234.683 | H12: 0.101 | I12: 1 | J12: 10-12;15 | K12: A;E | L12: 46158 | M12: =L12-D12 -> 112 | T12: =G12 -> 12234.683 | U12: =T12*N12/100 -> 0
A13: 2 | B13: 12 | C13: SIR 20 | D13: 46048 | E13: 19912 | F13: 70.643333 | G13: =E13*F13/100 -> 14066.501 | H13: 0.11766667 | I13: 1 | J13: 15;15;14 | K13: E,D;C;E | L13: 46158 | M13: =L13-D13 -> 110 | T13: =G13 -> 14066.501 | U13: =T13*N13/100 -> 0
A14: 3 | B14: 12 | C14: SIR 20 | D14: 46048 | E14: 4082 | F14: 74.223333 | G14: =E14*F14/100 -> 3029.7965 | H14: 0.10666667 | I14: 1 | J14: 13 | K14: E | L14: 46193 | M14: =L14-D14 -> 145 | N14: 98.966667 | O14: 37.333333 | P14: 24.333333 | Q14: 65.266667 | S14: 71.166667 | T14: =G14 -> 3029.7965 | U14: =T14*N14/100 -> 2998.4886
A15: 3 | B15: 13 | C15: SIR 20 | D15: 46049 | E15: 26894 | F15: 70.483333 | G15: =E15*F15/100 -> 18955.788 | H15: 0.10666667 | I15: 1;2 | J15: 13;15 | K15: D,C;A,B | L15: 46158 | M15: =L15-D15 -> 109 | T15: =G15 -> 18955.788 | U15: =T15*N15/100 -> 0
A16: 3 | B16: 14 | C16: SIR 20 | D16: 46050 | E16: 20056 | F16: 72.966667 | G16: =E16*F16/100 -> 14634.195 | H16: 0.10933333 | I16: 2 | J16: 15;14 | K16: D,C,E;D,C | L16: 46158 | M16: =L16-D16 -> 108 | T16: =G16 -> 14634.195 | U16: =T16*N16/100 -> 0
A17: 4 | B17: 20 | C17: SIR 20 | D17: 46080 | E17: 9416 | F17: 73.1 | G17: =E17*F17/100 -> 6883.096 | H17: 0.105 | I17: 2 | J17: 7 | K17: C,D | L17: 46092 | M17: =L17-D17 -> 12 | N17: 88.733333 | R17: 0.122 | T17: =G17 -> 6883.096 | U17: =T17*N17/100 -> 6107.6005
A18: 4 | B18: 21 | C18: SIR 20 | D18: 46081 | E18: 9948 | F18: 73.506667 | G18: =E18*F18/100 -> 7312.4432 | H18: 0.11 | I18: 2 | J18: 7;6 | K18: C;E | L18: 46158 | M18: =L18-D18 -> 77 | N18: 99.16 | O18: 40 | P18: 28.333333 | Q18: 71 | R18: 0.13533333 | S18: 82 | T18: =G18 -> 7312.4432 | U18: =T18*N18/100 -> 7251.0187
A19: 4 | B19: 22 | C19: SIR 20 | D19: 46083 | E19: 12128 | F19: 71.876667 | G19: =E19*F19/100 -> 8717.2021 | H19: 0.11533333 | I19: 2 | J19: 6 | K19: D,C | L19: 46127 | M19: =L19-D19 -> 44 | N19: 97.096667 | O19: 39 | P19: 29.333333 | Q19: 75 | R19: 0.10933333 | S19: 77.333333 | T19: =G19 -> 8717.2021 | U19: =T19*N19/100 -> 8464.1127
A20: 4 | B20: 23 | C20: SIR 20 | D20: 46084 | E20: 12158 | F20: 74.982 | G20: =E20*F20/100 -> 9116.3116 | H20: 0.12233333 | I20: 2 | J20: 5 | K20: E,D | L20: 46127 | M20: =L20-D20 -> 43 | N20: 97.096667 | O20: 39 | P20: 29.333333 | Q20: 75 | R20: 0.10933333 | S20: 77.333333 | T20: =G20 -> 9116.3116 | U20: =T20*N20/100 -> 8851.6346
A21: 4 | B21: 24 | C21: SIR 20 | D21: 46085 | E21: 10038 | F21: 76.866667 | G21: =E21*F21/100 -> 7715.876 | H21: 0.11733333 | I21: 2 | J21: 4 | K21: E,D | L21: 46127 | M21: =L21-D21 -> 42 | N21: 97.096667 | O21: 39 | P21: 29.333333 | Q21: 75 | R21: 0.10933333 | S21: 77.333333 | T21: =G21 -> 7715.876 | U21: =T21*N21/100 -> 7491.8584
A22: 5 | B22: 15 | C22: SIR 20 | D22: 46072 | E22: 3708 | F22: 73.023333 | G22: =E22*F22/100 -> 2707.7052 | H22: 0.115 | I22: 2 | J22: 12 | K22: E | L22: 46158 | M22: =L22-D22 -> 86 | N22: 98.613333 | O22: 43 | P22: 31.666667 | Q22: 73.666667 | R22: 0.116 | S22: 79.833333 | T22: =G22 -> 2707.7052 | U22: =T22*N22/100 -> 2670.1584
A23: 5 | B23: 16 | C23: SIR 20 | D23: 46076 | E23: 10374 | F23: 71.393333 | G23: =E23*F23/100 -> 7406.3444 | H23: 0.105 | I23: 2 | J23: 12 | K23: E,D | L23: 46092 | M23: =L23-D23 -> 16 | N23: 90.616667 | R23: 0.104 | T23: =G23 -> 7406.3444 | U23: =T23*N23/100 -> 6711.3824
A24: 5 | B24: 17 | C24: SIR 20 | D24: 46077 | E24: 15858 | F24: 71.01 | G24: =E24*F24/100 -> 11260.766 | H24: 0.111 | I24: 2 | J24: 12 | K24: C | L24: 46092 | M24: =L24-D24 -> 15 | N24: 89.936667 | R24: 0.10566667 | T24: =G24 -> 11260.766 | U24: =T24*N24/100 -> 10127.557
A25: 5 | B25: 18 | C25: SIR 20 | D25: 46078 | E25: 14402 | F25: 74.656667 | G25: =E25*F25/100 -> 10752.053 | H25: 0.11133333 | I25: 2 | J25: 10 | K25: E,D | L25: 46092 | M25: =L25-D25 -> 14 | N25: 88.536667 | R25: 0.115 | T25: =G25 -> 10752.053 | U25: =T25*N25/100 -> 9519.5094
A26: 5 | B26: 19 | C26: SIR 20 | D26: 46079 | E26: 11430 | F26: 71.606667 | G26: =E26*F26/100 -> 8184.642 | H26: 0.108 | I26: 2 | J26: 9 | K26: E | L26: 46092 | M26: =L26-D26 -> 13 | N26: 91.136667 | R26: 0.106 | T26: =G26 -> 8184.642 | U26: =T26*N26/100 -> 7459.2099
A27: 6 | B27: 24 | C27: SIR 20 | D27: 46085 | E27: 4538 | F27: 72.623333 | G27: =E27*F27/100 -> 3295.6469 | H27: 0.121 | I27: 2 | J27: 2 | K27: D,E | L27: 46128 | M27: =L27-D27 -> 43 | N27: 98.926667 | O27: 39.666667 | P27: 28.333333 | Q27: 71.333333 | R27: 0.11266667 | S27: 79.666667 | T27: =G27 -> 3295.6469 | U27: =T27*N27/100 -> 3260.2736
A28: 6 | B28: 25 | C28: SIR 20 | D28: 46086 | E28: 9020 | F28: 71.123333 | G28: =E28*F28/100 -> 6415.3247 | H28: 0.12166667 | I28: 2 | J28: 2 | K28: D,E,C | L28: 46128 | M28: =L28-D28 -> 42 | N28: 97.243333 | O28: 35.333333 | P28: 26.666667 | Q28: 75.333333 | R28: 0.10833333 | S28: 77.166667 | T28: =G28 -> 6415.3247 | U28: =T28*N28/100 -> 6238.4756
A29: 6 | B29: 26 | C29: SIR 20 | D29: 46087 | E29: 15316 | F29: 72.463333 | G29: =E29*F29/100 -> 11098.484 | H29: 0.13233333 | I29: 2 | J29: 2;5;6 | K29: C,D;B,A;A,B | L29: 46128 | M29: =L29-D29 -> 41 | N29: 97.106667 | O29: 38.333333 | P29: 28.666667 | Q29: 74.666667 | R29: 0.11133333 | S29: 78.166667 | T29: =G29 -> 11098.484 | U29: =T29*N29/100 -> 10777.368
A30: 6 | B30: 27 | C30: SIR 20 | D30: 46090 | E30: 16102 | F30: 70.64 | G30: =E30*F30/100 -> 11374.453 | H30: 0.11866667 | I30: 2 | J30: 6;7 | K30: A,B | L30: 46128 | M30: =L30-D30 -> 38 | N30: 96.496667 | O30: 38.333333 | P30: 29 | Q30: 75.333333 | R30: 0.10833333 | S30: 77.333333 | T30: =G30 -> 11374.453 | U30: =T30*N30/100 -> 10975.968
A31: 6 | B31: 28 | C31: SIR 20 | D31: 46091 | E31: 6926 | F31: 74.016667 | G31: =E31*F31/100 -> 5126.3943 | H31: 0.11566667 | I31: 2 | J31: 7;8 | K31: A,B;B,A | L31: 46132 | M31: =L31-D31 -> 41 | N31: 97.293333 | O31: 38.333333 | P31: 29 | Q31: 75.666667 | R31: 0.111 | S31: 311.33333 | T31: =G31 -> 5126.3943 | U31: =T31*N31/100 -> 4987.6399
A32: 7 | B32: 29 | C32: SIR 20 | D32: 46091 | E32: 6088 | F32: 74.123333 | G32: =E32*F32/100 -> 4512.6285 | H32: 0.11766667 | I32: 2 | J32: 10 | K32: A | L32: 46158 | M32: =L32-D32 -> 67 | N32: 98.723333 | O32: 44.666667 | P32: 32.333333 | Q32: 72.333333 | S32: 84.666667 | T32: =G32 -> 4512.6285 | U32: =T32*N32/100 -> 4455.0173
A33: 7 | B33: 30 | C33: SIR 20 | D33: 46092 | E33: 12468 | F33: 73.646667 | G33: =E33*F33/100 -> 9182.2664 | H33: 0.11033333 | I33: 2 | J33: 10;11 | K33: A,B;A | L33: 46127 | M33: =L33-D33 -> 35 | N33: 96.953333 | O33: 39.333333 | P33: 29 | Q33: 73.666667 | R33: 0.106 | S33: 77 | T33: =G33 -> 9182.2664 | U33: =T33*N33/100 -> 8902.5134
A34: 7 | B34: 31 | C34: SIR 20 | D34: 46093 | E34: 13328 | F34: 72.226667 | G34: =E34*F34/100 -> 9626.3701 | I34: 2 | J34: 10;11 | K34: A,B;A | L34: 46127 | M34: =L34-D34 -> 34 | N34: 96.84 | O34: 39.666667 | P34: 29.333333 | Q34: 74 | R34: 0.115 | S34: 76.666667 | T34: =G34 -> 9626.3701 | U34: =T34*N34/100 -> 9322.1768
A35: 7 | B35: 32 | C35: SIR 20 | D35: 46094 | E35: 14370 | F35: 72.096667 | G35: =E35*F35/100 -> 10360.291 | H35: 0.10566667 | I35: 2 | J35: 12;13 | K35: A,B;A | L35: 46127 | M35: =L35-D35 -> 33 | N35: 96.84 | O35: 39.666667 | P35: 29.333333 | Q35: 74 | R35: 0.115 | S35: 76.666667 | T35: =G35 -> 10360.291 | U35: =T35*N35/100 -> 10032.906
A36: 7 | B36: 33 | C36: SIR 20 | D36: 46095 | E36: 5304 | F36: 73.813333 | G36: =E36*F36/100 -> 3915.0592 | H36: 0.12066667 | I36: 2 | J36: 13 | K36: B | L36: 46127 | M36: =L36-D36 -> 32 | N36: 96.93 | O36: 38.666667 | P36: 28.333333 | Q36: 73.333333 | R36: 0.106 | S36: 77.333333 | T36: =G36 -> 3915.0592 | U36: =T36*N36/100 -> 3794.8669
A37: 8 | B37: 34 | C37: SIR 20 | D37: 46113 | E37: 2291 | F37: 72.906667 | G37: =E37*F37/100 -> 1670.2917 | H37: 0.13466667 | I37: 1 | J37: 12 | K37: E | L37: 46158 | M37: =L37-D37 -> 45 | N37: 97.706667 | O37: 42.666667 | P37: 30.666667 | Q37: 72 | S37: 81.5 | T37: =G37 -> 1670.2917 | U37: =T37*N37/100 -> 1631.9864
A38: 8 | B38: 35 | C38: SIR 20 | D38: 46114 | E38: 17316 | F38: 73.25 | G38: =E38*F38/100 -> 12683.97 | H38: 0.102 | I38: 1 | J38: 12 | K38: D,C;E,D | L38: 46129 | M38: =L38-D38 -> 15 | N38: 87.87 | O38: 30.333333 | P38: 21.666667 | Q38: 71.333333 | R38: 0.11533333 | S38: 71.333333 | T38: =G38 -> 12683.97 | U38: =T38*N38/100 -> 11145.404
A39: 8 | B39: 36 | C39: SIR 20 | D39: 46116 | E39: 11557 | F39: 69.753333 | G39: =E39*F39/100 -> 8061.3927 | H39: 0.108 | I39: 1 | J39: 11;10 | K39: D,C;E,D | L39: 46132 | M39: =L39-D39 -> 16 | N39: 92.18 | O39: 38 | P39: 30.666667 | Q39: 80.666667 | R39: 0.11133333 | S39: 69.5 | T39: =G39 -> 8061.3927 | U39: =T39*N39/100 -> 7430.9918
A40: 8 | B40: 37 | C40: SIR 20 | D40: 46118 | E40: 26278 | F40: 69.45 | G40: =E40*F40/100 -> 18250.071 | H40: 0.118 | I40: 1 | J40: 10;9 | K40: D,C;E | L40: 46132 | M40: =L40-D40 -> 14 | N40: 91.31 | O40: 36.666667 | P40: 28.666667 | Q40: 78 | R40: 0.11233333 | S40: 68 | T40: =G40 -> 18250.071 | U40: =T40*N40/100 -> 16664.14
...

Sheet Dry
A1: Batch | B1: Process ke-n | C1: Date of Production | D1: Lantai | E1: Block | F1: Kamar | G1: Left - Blanket Kering (CP8) | H1: Middle - Blanket Kering (CP8) | I1: Right - Blanket Kering (CP8) | J1: Average (10mm ± 2mm) - Blanket Kering (CP8) | K1: Date DRC Wet | L1: % DRC Wet | M1: Date DRC Dry | N1: % DRC Dry | O1: P0 | P1: PRI | Q1: MV | R1: Dirt | S1: Hanging Days | T1: SHREDDER 2 SIZE (5mm ± 1mm) | U1: TROLLEY SIZE (cm) | V1: Drayer A - Burner1 | W1: Drayer A - Burner2 | X1: Drayer A - Cycle | Y1: Drayer A - P0 | Z1: Drayer A - PRI | AA1: Drayer A - MV | AB1: Drayer B - Burner1 | AC1: Drayer B - Burner2 | AD1: Drayer B - Cycle | AE1: Drayer B - P0 | AF1: Drayer B - PRI | AG1: Drayer B - MV | AH1: Temp. Biscuit (Max. 50°C) | AI1: Tinggi Bale A | AJ1: Tinggi Bale B | AK1: Tinggi Bale C | AL1: Temp. Bale (Max. 50°C) | AM1: Weight Contamination (g) | AN1: Type Contamination | AO1: Produk Sesuai (Bale) | AP1: Produk Sesuai (Kgs) | AQ1: Produk Sesuai (Pallet) | AR1: Produk Tidak Sesuai (Bale) | AS1: Produk Tidak Sesuai (Kgs) | AT1: Produk Tidak Sesuai (Pallet) | AU1: Total Produk (Bale) | AV1: Total Produk (Kgs) | AW1: Total Produk (Pallet) | AX1: Pallet No. (Awal) | AY1: - | AZ1: Pallet No. (Akhir) | BA1: Grade
A2: 27 | B2: 1 | C2: 46142 | D2: 1 | E2: 9 | F2: C,D | G2: 17.5 | H2: 11.5 | I2: 13.96 | J2: =AVERAGE(G2:I2) -> 14.32 | K2: 46010 | L2: 70.39 | M2: 46142 | N2: 94.84 | O2: 41 | P2: 82 | Q2: 77.5 | R2: 0.12 | S2: =M2-K2 -> 132 | T2: 11.38 | U2: 37.5 | V2: 100.66 | W2: 66 | X2: 7 | Y2: 39.5 | Z2: 74.25 | AA2: 75.37 | AH2: 55.875 | AO2: 2 | AP2: =AO2*35 -> 70 | AQ2: =AP2/1260 -> 0.055555556 | AR2: 24 | AS2: =AR2*35 -> 840 | AT2: =AS2/1260 -> 0.66666667 | AU2: =AO2+AR2 -> 26 | AV2: =AP2+AS2 -> 910 | AW2: =AQ2+AT2 -> 0.72222222 | AX2: 1 | AY2: - | AZ2: 2 | BA2: SIR 20
A3: 27 | B3: 2 | C3: 46144 | AK3: √ | AL3: 34.2 | AM3: 8.8 | AN3: Kayu. | BA3: SIR 20
A4: 27 | B4: 3 | C4: 46146 | D4: 1 | E4: 8 | F4: E | G4: 14.13 | H4: 10.83 | I4: 17.1 | J4: =AVERAGE(G4:I4) -> 14.02 | K4: 46008 | L4: 73.12 | M4: 46146 | N4: 98.77 | O4: 41 | P4: 82 | Q4: 77.5 | R4: 0.12 | S4: =M4-K4 -> 138 | T4: 10.955 | U4: 37.5 | AX4: 2 | AY4: - | AZ4: 2 | BA4: SIR 20
A5: 27 | B5: 4 | C5: 46147 | Y5: 30.8 | Z5: 71 | AA5: 74.1 | AB5: 110.75 | AC5: 72.5 | AD5: 7 | AE5: 38 | AF5: 69.5 | AG5: 72.25 | AI5: √ | AJ5: √ | AL5: 48.23 | AM5: 50 | AN5: Plastik | AO5: 0 | AP5: =AO5*35 -> 0 | AQ5: =AP5/1260 -> 0 | AR5: 77 | AS5: =AR5*35 -> 2695 | AT5: =AS5/1260 -> 2.1388889 | AU5: =AO5+AR5 -> 77 | AV5: =AP5+AS5 -> 2695 | AW5: =AQ5+AT5 -> 2.1388889 | AX5: 3 | AY5: - | AZ5: 4 | BA5: SIR 20
A6: 27 | B6: 5 | C6: 46148 | D6: 1 | E6: 8;7 | F6: E;C,D | G6: 14.52 | H6: 15.29 | I6: 12.97 | J6: =AVERAGE(G6:I6) -> 14.26 | K6: 46008 | L6: 73.12 | M6: 46147 | N6: 98.77 | S6: =M6-K6 -> 139 | T6: 10.535 | U6: 38 | V6: 115 | W6: 47 | X6: 7 | BA6: SIR 20
A7: 27 | B7: 6 | C7: 46149 | V7: 101 | W7: 113 | X7: 7 | Y7: 35.5 | Z7: 70 | AA7: 71.5 | AE7: 36 | AF7: 72.33 | AG7: 71.58 | AH7: 100.66 | AI7: √ | AJ7: √ | AK7: √ | AL7: 54.33 | AM7: 25 | AN7: Cat,Plastik,Tatal | AO7: 17 | AP7: =AO7*35 -> 595 | AQ7: =AP7/1260 -> 0.47222222 | AR7: 1 | AS7: =AR7*35 -> 35 | AT7: =AS7/1260 -> 0.027777778 | AU7: =AO7+AR7 -> 18 | AV7: =AP7+AS7 -> 630 | AW7: =AQ7+AT7 -> 0.5 | AX7: 4 | AY7: - | AZ7: 4 | BA7: SIR 20
A8: 28 | B8: 7 | C8: 46150 | D8: 1 | E8: 7 | F8: C-E | G8: 14.91 | H8: 10.53 | I8: 13.97 | J8: =AVERAGE(G8:I8) -> 13.136667 | K8: 46013 | L8: 76.05 | M8: 46150 | N8: 96.18 | O8: 37 | P8: 84 | Q8: 69.67 | R8: 0.122 | S8: =M8-K8 -> 137 | T8: 30.5 | AB8: 135.2 | AC8: 52 | AD8: 7 | AM8: 168 | AN8: Plastik,tatal | AO8: 134 | AP8: =AO8*35 -> 4690 | AQ8: =AP8/1260 -> 3.7222222 | AR8: 7 | AS8: =AR8*35 -> 245 | AT8: =AS8/1260 -> 0.19444444 | AU8: =AO8+AR8 -> 141 | AV8: =AP8+AS8 -> 4935 | AW8: =AQ8+AT8 -> 3.9166667 | AX8: 5 | AY8: - | AZ8: 8 | BA8: SIR 20
A9: 28 | B9: 8 | C9: 46151 | D9: 1 | E9: 6 | F9: E,D | G9: 16.41 | H9: 12.04 | I9: 14.8 | J9: =AVERAGE(G9:I9) -> 14.416667 | K9: 46013 | L9: 76.05 | M9: 46151 | N9: 96.18 | S9: =M9-K9 -> 138 | T9: 13.42 | U9: 31 | AB9: 117.75 | AC9: 88 | AD9: 7 | AE9: 41 | AF9: 70 | AG9: 72.8 | AL9: 63.2 | AM9: 4.8 | AN9: Plastik,tatal | AO9: 29 | AP9: =AO9*35 -> 1015 | AQ9: =AP9/1260 -> 0.80555556 | AR9: 0 | AS9: =AR9*35 -> 0 | AT9: =AS9/1260 -> 0 | AU9: =AO9+AR9 -> 29 | AV9: =AP9+AS9 -> 1015 | AW9: =AQ9+AT9 -> 0.80555556 | AX9: 8 | AY9: - | AZ9: 9 | BA9: SIR 20
A10: 28 | B10: 9 | C10: 46153 | D10: 1 | E10: 6;5 | F10: E;D,E | G10: 19.71 | H10: 14.02 | I10: 14.92 | J10: =AVERAGE(G10:I10) -> 16.216667 | K10: 46013 | L10: 76.05 | M10: 46153 | N10: 95.69 | S10: =M10-K10 -> 140 | T10: 13.04 | U10: 30.5 | AB10: 104.5 | AC10: 87.25 | AD10: 7 | AE10: 38 | AF10: 72.33 | AG10: 72.73 | AI10: √ | AJ10: √ | AL10: 40.77 | AM10: 2.7643 | AN10: Platik,kayu,benang | AO10: 229 | AP10: =AO10*35 -> 8015 | AQ10: =AP10/1260 -> 6.3611111 | AR10: 5 | AS10: =AR10*35 -> 175 | AT10: =AS10/1260 -> 0.13888889 | AU10: =AO10+AR10 -> 234 | AV10: =AP10+AS10 -> 8190 | AW10: =AQ10+AT10 -> 6.5 | AX10: 9 | AY10: - | AZ10: 15 | BA10: SIR 20
A11: 28 | B11: 10 | C11: 46154 | D11: 1 | E11: 4 | F11: C-E | G11: 17.32 | H11: 13.2 | I11: 18.05 | J11: =AVERAGE(G11:I11) -> 16.19 | K11: 46020 | L11: 65.54 | M11: 46154 | N11: 93.71 | S11: =M11-K11 -> 134 | T11: 12.872 | U11: 31.6 | AB11: 97.8 | AC11: 92.6 | AD11: 10 | AE11: 37.9 | AF11: 70.94 | AG11: 73.75 | AH11: 42.8 | AI11: √ | AJ11: √ | AL11: 37.46 | AM11: 35.2709 | AN11: Plastik,kayu,benang | AO11: 225 | AP11: =AO11*35 -> 7875 | AQ11: =AP11/1260 -> 6.25 | AR11: 1 | AS11: =AR11*35 -> 35 | AT11: =AS11/1260 -> 0.027777778 | AU11: =AO11+AR11 -> 226 | AV11: =AP11+AS11 -> 7910 | AW11: =AQ11+AT11 -> 6.2777778 | AX11: 16 | AY11: - | AZ11: 22 | BA11: SIR 20
A12: 28 | B12: 11 | C12: 46155 | AI12: √ | AJ12: √ | AL12: 33.83 | AM12: 1.5243 | AN12: Plastik,tatal | AO12: 37 | AP12: =AO12*35 -> 1295 | AQ12: =AP12/1260 -> 1.0277778 | AR12: 0 | AS12: =AR12*35 -> 0 | AT12: =AS12/1260 -> 0 | AU12: =AO12+AR12 -> 37 | AV12: =AP12+AS12 -> 1295 | AW12: =AQ12+AT12 -> 1.0277778 | AX12: 22 | AY12: - | AZ12: 23 | BA12: SIR 20
A13: 28 | B13: 12 | C13: 46157 | D13: 1 | E13: 4 | F13: C-E | G13: 16.77 | H13: 11.8 | I13: 14.53 | J13: =AVERAGE(G13:I13) -> 14.366667 | K13: 46020 | L13: 65.54 | M13: 46157 | N13: 93.71 | S13: =M13-K13 -> 137 | T13: 13.37 | U13: 31 | AB13: 86.33 | AC13: 81.33 | AD13: 10 | AE13: 39.08 | AF13: 70.13 | AG13: 73.86 | AH13: 32.66 | AI13: √ | AJ13: √ | AL13: 32.145 | AM13: 60.6124 | AN13: Tatal,plastik,benang | AO13: 310 | AP13: =AO13*35 -> 10850 | AQ13: =AP13/1260 -> 8.6111111 | AR13: 6 | AS13: =AR13*35 -> 210 | AT13: =AS13/1260 -> 0.16666667 | AU13: =AO13+AR13 -> 316 | AV13: =AP13+AS13 -> 11060 | AW13: =AQ13+AT13 -> 8.7777778 | AX13: 23 | AY13: - | AZ13: 31 | BA13: SIR 20
A14: 28 | B14: 13 | C14: 46160 | D14: 1 | E14: 2 | F14: A-E | G14: 14.07 | H14: 12.31 | I14: 14.51 | J14: =AVERAGE(G14:I14) -> 13.63 | K14: 46020 | L14: 65.54 | M14: 46160 | N14: 93.71 | S14: =M14-K14 -> 140 | T14: 12.33 | U14: 47.5 | AB14: 97.85 | AC14: 83 | AD14: 7 | AE14: 40.91 | AF14: 65.81 | AG14: 75.38 | AI14: √ | AJ14: √ | AL14: 39.05 | AM14: 120.204 | AN14: Platik,Kayu,Benang | AP14: =AO14*35 -> 0 | AQ14: =AP14/1260 -> 0 | AS14: =AR14*35 -> 0 | AT14: =AS14/1260 -> 0 | AU14: =AO14+AR14 -> 0 | AV14: =AP14+AS14 -> 0 | AW14: =AQ14+AT14 -> 0 | AX14: 31 | AY14: - | AZ14: 34 | BA14: SIR 20
A15: 28 | B15: 14 | C15: 46161 | D15: 1 | E15: 3-4 | F15: A-B | G15: 14.95 | H15: 13.91 | I15: 16.64 | J15: =AVERAGE(G15:I15) -> 15.166667 | K15: 46022 | L15: 64.49 | M15: 46161 | N15: 93.65 | S15: =M15-K15 -> 139 | T15: 12.07 | U15: 31.25 | AB15: 100.33 | AC15: 61.33 | AD15: 8 | AI15: √ | AJ15: √ | AL15: 35.72 | AM15: 200 | AN15: Platik,tali,kayu | AO15: 127 | AP15: =AO15*35 -> 4445 | AQ15: =AP15/1260 -> 3.5277778 | AR15: =2+39 -> 41 | AS15: =AR15*35 -> 1435 | AT15: =AS15/1260 -> 1.1388889 | AU15: =AO15+AR15 -> 168 | AV15: =AP15+AS15 -> 5880 | AW15: =AQ15+AT15 -> 4.6666667 | AX15: 34 | AY15: - | AZ15: 38 | BA15: SIR 20
A16: 28 | B16: 15 | C16: 46162 | D16: 2 | E16: 3-4 | F16: A-B | G16: 21.4 | H16: 16.48 | I16: 19.14 | J16: =AVERAGE(G16:I16) -> 19.006667 | K16: 46022 | L16: 64.49 | M16: 46162 | N16: 96.4 | S16: =M16-K16 -> 140 | T16: 17.31 | U16: 31.5 | AB16: 101.33 | AC16: 86 | AD16: 8 | AE16: 42.7 | AF16: 65.84 | AG16: 77.84 | AH16: 39.5 | AI16: √ | AJ16: √ | AL16: 35.93 | AM16: 25 | AN16: Plastik.Tali.Tatal | AO16: 187 | AP16: =AO16*35 -> 6545 | AQ16: =AP16/1260 -> 5.1944444 | AR16: 6 | AS16: =AR16*35 -> 210 | AT16: =AS16/1260 -> 0.16666667 | AU16: =AO16+AR16 -> 193 | AV16: =AP16+AS16 -> 6755 | AW16: =AQ16+AT16 -> 5.3611111 | AX16: 38 | AY16: - | AZ16: 43 | BA16: SIR 20
A17: 4 | B17: 16 | C17: 46162 | AP17: =AO17*35 -> 0 | AQ17: =AP17/1260 -> 0 | AS17: =AR17*35 -> 0 | AT17: =AS17/1260 -> 0 | AU17: =AO17+AR17 -> 0 | AV17: =AP17+AS17 -> 0 | AW17: =AQ17+AT17 -> 0 | AY17: - | BA17: SIR 20
A18: 4 | B18: 17 | C18: 46163 | D18: 2 | E18: 6-7 | F18: C-E | G18: 19.31 | H18: 15.51 | I18: 22.61 | J18: =AVERAGE(G18:I18) -> 19.143333 | K18: 46081 | L18: 73.51 | M18: 46163 | N18: 99.16 | O18: 40 | P18: 71 | Q18: 82 | R18: 0.135 | S18: =M18-K18 -> 82 | T18: 21.49 | U18: 31.25 | AB18: 96.71 | AC18: 87.14 | AD18: 8 | AE18: 44.7 | AF18: 63.11 | AG18: 82.21 | AH18: 48 | AI18: √ | AJ18: √ | AL18: 38.83 | AM18: 30 | AN18: Plastik.tatal | AO18: 354 | AP18: =AO18*35 -> 12390 | AQ18: =AP18/1260 -> 9.8333333 | AR18: 9 | AS18: =AR18*35 -> 315 | AT18: =AS18/1260 -> 0.25 | AU18: =AO18+AR18 -> 363 | AV18: =AP18+AS18 -> 12705 | AW18: =AQ18+AT18 -> 10.083333 | AX18: 43 | AY18: - | AZ18: 54 | BA18: SIR 20
A19: 4 | B19: 18 | C19: 46164 | D19: 2 | E19: 6-5 | F19: C-D | G19: 21.29 | H19: 16.49 | I19: 21.5 | J19: =AVERAGE(G19:I19) -> 19.76 | K19: 46081 | L19: 73.51 | M19: 46164 | N19: 99.16 | S19: =M19-K19 -> 83 | T19: 18.23 | U19: 32 | AB19: 96.6 | AC19: 87.8 | AD19: 8 | AE19: 46.06 | AF19: 61.07 | AG19: 85.48 | AI19: √ | AJ19: √ | AL19: 38.4 | AM19: 35 | AN19: Plastik.tali | AO19: 208 | AP19: =AO19*35 -> 7280 | AQ19: =AP19/1260 -> 5.7777778 | AR19: 4 | AS19: =AR19*35 -> 140 | AT19: =AS19/1260 -> 0.11111111 | AU19: =AO19+AR19 -> 212 | AV19: =AP19+AS19 -> 7420 | AW19: =AQ19+AT19 -> 5.8888889 | AX19: 54 | AY19: - | AZ19: 60 | BA19: SIR 20
A20: 4 | B20: 19 | C20: 46165 | AB20: 103.5 | AC20: 94 | AD20: 8 | AE20: 46 | AF20: 64.12 | AG20: 84.1 | AH20: 40.5 | AI20: √ | AJ20: √ | AL20: 32.57 | AM20: 10 | AN20: plastik,benang | AO20: 130 | AP20: =AO20*35 -> 4550 | AQ20: =AP20/1260 -> 3.6111111 | AR20: 1 | AS20: =AR20*35 -> 35 | AT20: =AS20/1260 -> 0.027777778 | AU20: =AO20+AR20 -> 131 | AV20: =AP20+AS20 -> 4585 | AW20: =AQ20+AT20 -> 3.6388889 | AX20: 60 | AY20: - | AZ20: 63 | BA20: SIR 20
A21: 4 | B21: 20 | C21: 46167 | AB21: 59.5 | AC21: 89.5 | AD21: 8 | AE21: 47.12 | AF21: 61.81 | AG21: 84.82 | AI21: √ | AJ21: √ | AL21: 32.05 | AM21: 75 | AN21: Tali,Plastik | AO21: 304 | AP21: =AO21*35 -> 10640 | AQ21: =AP21/1260 -> 8.4444444 | AR21: 19 | AS21: =AR21*35 -> 665 | AT21: =AS21/1260 -> 0.52777778 | AU21: =AO21+AR21 -> 323 | AV21: =AP21+AS21 -> 11305 | AW21: =AQ21+AT21 -> 8.9722222 | AX21: 63 | AY21: - | AZ21: 72 | BA21: SIR 20
A22: 4 | B22: 21 | C22: 46171 | D22: 2 | E22: 4 | F22: E-D | G22: 18.84 | H22: 18.14 | I22: 20.93 | J22: =AVERAGE(G22:I22) -> 19.303333 | K22: 46085 | L22: 76.87 | M22: 46171 | N22: 99.16 | S22: =M22-K22 -> 86 | AP22: =AO22*35 -> 0 | AQ22: =AP22/1260 -> 0 | AS22: =AR22*35 -> 0 | AT22: =AS22/1260 -> 0 | AU22: =AO22+AR22 -> 0 | AV22: =AP22+AS22 -> 0 | AW22: =AQ22+AT22 -> 0 | BA22: SIR 20
A23: 4 | B23: 22 | C23: 46172 | D23: 2 | E23: 4 | F23: D-E | G23: 22.01 | H23: 14.82 | I23: 17.5 | J23: =AVERAGE(G23:I23) -> 18.11 | K23: 46085 | L23: 76.87 | M23: 46172 | N23: 99.16 | S23: =M23-K23 -> 87 | AB23: 100.5 | AC23: 87.25 | AD23: 8 | AE23: 47.87 | AF23: 57.87 | AG23: 84.07 | AH23: 43 | AI23: √ | AJ23: √ | AL23: 35.92 | AM23: 5 | AN23: Plastik,Tatal,Tali | AP23: =AO23*35 -> 0 | AQ23: =AP23/1260 -> 0 | AS23: =AR23*35 -> 0 | AT23: =AS23/1260 -> 0 | AU23: =AO23+AR23 -> 0 | AV23: =AP23+AS23 -> 0 | AW23: =AQ23+AT23 -> 0 | AX23: 72 | AY23: - | AZ23: 75 | BA23: SIR 20
A24: 5 | B24: 23 | C24: 46175 | D24: 2 | E24: 12 | F24: D-E | G24: 20.12 | H24: 13.77 | I24: 18.08 | J24: =AVERAGE(G24:I24) -> 17.323333 | K24: 46072 | L24: 73.02 | M24: 46175 | N24: 98.61 | O24: 43 | P24: 74 | Q24: 79.8 | R24: 0.116 | S24: =M24-K24 -> 103 | T24: 14.84 | U24: 31.75 | AB24: 96.75 | AC24: 84 | AD24: 8 | AE24: 48.16 | AF24: 75.58 | AG24: 83.73 | AH24: 35.8 | AI24: √ | AJ24: √ | AL24: 37.41 | AM24: 10 | AN24: Plastik,Tali | AO24: 175 | AP24: =AO24*35 -> 6125 | AQ24: =AP24/1260 -> 4.8611111 | AR24: 10 | AS24: =AR24*35 -> 350 | AT24: =AS24/1260 -> 0.27777778 | AU24: =AO24+AR24 -> 185 | AV24: =AP24+AS24 -> 6475 | AW24: =AQ24+AT24 -> 5.1388889 | AX24: 76 | AY24: - | AZ24: 81 | BA24: SIR 20
A25: 5 | B25: 24 | C25: 46176 | D25: 2 | E25: 11 | F25: E-D | G25: 17.75 | H25: 12.13 | I25: 21.81 | J25: =AVERAGE(G25:I25) -> 17.23 | K25: 46077 | L25: 71.01 | M25: 46176 | N25: 98.61 | S25: =M25-K25 -> 99 | T25: 16.09 | U25: 28.5 | AB25: 96.66 | AC25: 89.16 | AD25: 8 | AE25: 45.95 | AF25: 93.95 | AG25: 84.17 | AH25: 38.16 | AI25: √ | AJ25: √ | AL25: 34.27 | AM25: 45 | AN25: Plastik,Tali,Tatal | AO25: 322 | AP25: =AO25*35 -> 11270 | AQ25: =AP25/1260 -> 8.9444444 | AR25: 27 | AS25: =AR25*35 -> 945 | AT25: =AS25/1260 -> 0.75 | AU25: =AO25+AR25 -> 349 | AV25: =AP25+AS25 -> 12215 | AW25: =AQ25+AT25 -> 9.6944444 | AX25: 81 | AY25: - | AZ25: 90 | BA25: SIR 20
A26: 5 | B26: 25 | C26: 46177 | D26: 2 | E26: 9/10 | F26: C-E | G26: 19.72 | H26: 14.12 | I26: 19.85 | J26: =AVERAGE(G26:I26) -> 17.896667 | K26: 46078 | L26: 73.13 | M26: 46177 | N26: 98.61 | S26: =M26-K26 -> 99 | T26: 14.2 | U26: 26.33 | AB26: 100 | AC26: 90.33 | AD26: 8 | AE26: 44.3 | AF26: 61.2 | AG26: 80.24 | AH26: 34.66 | AI26: √ | AJ26: √ | AL26: 32.31 | AM26: 20 | AN26: Plastik,Tatal | AO26: 117 | AP26: =AO26*35 -> 4095 | AQ26: =AP26/1260 -> 3.25 | AR26: 66 | AS26: =AR26*35 -> 2310 | AT26: =AS26/1260 -> 1.8333333 | AU26: =AO26+AR26 -> 183 | AV26: =AP26+AS26 -> 6405 | AW26: =AQ26+AT26 -> 5.0833333 | AX26: 90 | AY26: - | AZ26: 93 | BA26: SIR 20
A27: 5 | B27: 26 | C27: 46178 | D27: 2 | E27: 9 | F27: D-E | G27: 21.94 | H27: 17.51 | I27: 13.17 | J27: =AVERAGE(G27:I27) -> 17.54 | K27: 46078 | L27: 71.61 | M27: 46178 | N27: 98.61 | S27: =M27-K27 -> 100 | T27: 10.9 | U27: 29.6 | AB27: 97.83 | AC27: 86.83 | AD27: 8 | AE27: 45.06 | AF27: 65.18 | AG27: 82.27 | AH27: 38 | AI27: √ | AJ27: √ | AL27: 34.83 | AM27: 25 | AN27: Platik,benang,Tatal | AO27: 176 | AP27: =AO27*35 -> 6160 | AQ27: =AP27/1260 -> 4.8888889 | AR27: 64 | AS27: =AR27*35 -> 2240 | AT27: =AS27/1260 -> 1.7777778 | AU27: =AO27+AR27 -> 240 | AV27: =AP27+AS27 -> 8400 | AW27: =AQ27+AT27 -> 6.6666667 | AX27: 93 | AY27: - | AZ27: 98 | BA27: SIR 20
A28: 5 | B28: 27 | C28: 46179 | AE28: 43 | AF28: 66.3 | AG28: 76.3 | AI28: √ | AJ28: √ | AL28: 32 | AM28: 10 | AN28: Plastik,Tali,tatal | AO28: 36 | AP28: =AO28*35 -> 1260 | AQ28: =AP28/1260 -> 1 | AR28: 86 | AS28: =AR28*35 -> 3010 | AT28: =AS28/1260 -> 2.3888889 | AU28: =AO28+AR28 -> 122 | AV28: =AP28+AS28 -> 4270 | AW28: =AQ28+AT28 -> 3.3888889 | AX28: 98 | AY28: - | AZ28: 99 | BA28: SIR 20
A29: 6 | B29: 28 | C29: 46181 | D29: 2 | E29: 2 | F29: C-E | G29: 17.22 | H29: 14.62 | I29: 17.5 | J29: =AVERAGE(G29:I29) -> 16.446667 | K29: 46085 | L29: 72.62 | M29: 46181 | N29: 98.93 | O29: 40 | P29: 71 | Q29: 79.7 | R29: 0.113 | S29: =M29-K29 -> 96 | T29: 30.24 | U29: 30.25 | AB29: 95.4 | AC29: 85 | AD29: 8 | AE29: 44.57 | AF29: 60.8 | AG29: 80.75 | AH29: 35.75 | AI29: √ | AJ29: √ | AL29: 37.83 | AM29: 30 | AN29: Plastik,Kayu | AO29: 185 | AP29: =AO29*35 -> 6475 | AQ29: =AP29/1260 -> 5.1388889 | AR29: 33 | AS29: =AR29*35 -> 1155 | AT29: =AS29/1260 -> 0.91666667 | AU29: =AO29+AR29 -> 218 | AV29: =AP29+AS29 -> 7630 | AW29: =AQ29+AT29 -> 6.0555556 | AX29: 99 | AY29: - | AZ29: 104 | BA29: SIR 20
A30: 6 | B30: 29 | C30: 46182 | D30: 2 | E30: 2 | F30: C-E | G30: 18.19 | H30: 15.47 | I30: 17.64 | J30: =AVERAGE(G30:I30) -> 17.1 | K30: 46085 | L30: 72.62 | M30: 46182 | N30: 98.93 | S30: =M30-K30 -> 97 | T30: 13.94 | U30: 33 | AB30: 97.16 | AC30: 91.16 | AD30: 8 | AE30: 45.61 | AF30: 56.13 | AG30: 84.78 | AH30: 37.16 | AI30: √ | AJ30: √ | AL30: 37.14 | AM30: 50 | AN30: Tatal,Plastik,Tali | AO30: 222 | AP30: =AO30*35 -> 7770 | AQ30: =AP30/1260 -> 6.1666667 | AR30: 118 | AS30: =AR30*35 -> 4130 | AT30: =AS30/1260 -> 3.2777778 | AU30: =AO30+AR30 -> 340 | AV30: =AP30+AS30 -> 11900 | AW30: =AQ30+AT30 -> 9.4444444 | AX30: 104 | AY30: - | AZ30: 110 | BA30: SIR 20
A31: 6 | B31: 30 | C31: 46183 | D31: 2 | E31: 7 | F31: A-B | G31: 17.2 | H31: 13.72 | I31: 15.72 | J31: =AVERAGE(G31:I31) -> 15.546667 | K31: 46090 | L31: 74.02 | M31: 46183 | N31: 98.93 | S31: =M31-K31 -> 93 | T31: 12.9 | U31: 31.33 | AB31: 100 | AC31: 96 | AD31: 8 | AE31: 45.75 | AF31: 61.86 | AG31: 83.6 | AH31: 35 | AI31: √ | AJ31: √ | AL31: 32.84 | AM31: 30 | AN31: Plastik.tatal | AO31: 155 | AP31: =AO31*35 -> 5425 | AQ31: =AP31/1260 -> 4.3055556 | AR31: 28 | AS31: =AR31*35 -> 980 | AT31: =AS31/1260 -> 0.77777778 | AU31: =AO31+AR31 -> 183 | AV31: =AP31+AS31 -> 6405 | AW31: =AQ31+AT31 -> 5.0833333 | AX31: 111 | AY31: - | AZ31: 115 | BA31: SIR 20
A32: 6 | B32: 31 | C32: 46184 | D32: 2 | E32: 7-8 | F32: A,B;A | G32: 18.51 | H32: 14.17 | I32: 19 | J32: =AVERAGE(G32:I32) -> 17.226667 | K32: 46090 | L32: 70.64 | M32: 46184 | N32: 98.93 | S32: =M32-K32 -> 94 | T32: 13.32 | U32: 32 | AB32: 96 | AC32: 93 | AD32: 8 | AE32: 36.5 | AF32: 64.76 | AG32: 68.35 | AH32: 33.55 | AI32: √ | AJ32: √ | AL32: 33.55 | AM32: 100 | AN32: Plastik,Tali,Benang | AO32: 285 | AP32: =AO32*35 -> 9975 | AQ32: =AP32/1260 -> 7.9166667 | AR32: 28 | AS32: =AR32*35 -> 980 | AT32: =AS32/1260 -> 0.77777778 | AU32: =AO32+AR32 -> 313 | AV32: =AP32+AS32 -> 10955 | AW32: =AQ32+AT32 -> 8.6944444 | AX32: 115 | AY32: - | AZ32: 123 | BA32: SIR 20
A33: 6 | B33: 32 | C33: 46185 | AI33: √ | AJ33: √ | AL33: 32.6 | AM33: 10 | AN33: Plastik,Tali,Kayu | AO33: 29 | AP33: =AO33*35 -> 1015 | AQ33: =AP33/1260 -> 0.80555556 | AR33: 3 | AS33: =AR33*35 -> 105 | AT33: =AS33/1260 -> 0.083333333 | AU33: =AO33+AR33 -> 32 | AV33: =AP33+AS33 -> 1120 | AW33: =AQ33+AT33 -> 0.88888889 | AX33: 123 | AY33: - | AZ33: 124 | BA33: SIR 20
A34: 7 | B34: 33 | C34: 46188 | D34: 2 | E34: 10-14 | F34: A-B | G34: 18.32 | H34: 13.07 | I34: 15.83 | J34: =AVERAGE(G34:I34) -> 15.74 | K34: 46091 | L34: 73.158 | M34: 46188 | N34: 99.02 | O34: 46 | P34: 69.5 | Q34: 78.5 | R34: 0.107 | S34: =M34-K34 -> 97 | T34: 12.732 | U34: 33 | AB34: 101 | AC34: 95.5 | AD34: 8 | AE34: 44.9 | AF34: 62.78 | AG34: 81.4 | AH34: 35.16 | AI34: √ | AJ34: √ | AL34: 34.015 | AM34: 40 | AN34: Kayu,Plastik,Benang | AO34: 287 | AP34: =AO34*35 -> 10045 | AQ34: =AP34/1260 -> 7.9722222 | AR34: 6 | AS34: =AR34*35 -> 210 | AT34: =AS34/1260 -> 0.16666667 | AU34: =AO34+AR34 -> 293 | AV34: =AP34+AS34 -> 10255 | AW34: =AQ34+AT34 -> 8.1388889 | AX34: 124 | AY34: - | AZ34: 131 | BA34: SIR 20
A35: 7 | B35: 34 | C35: 46190 | D35: 2 | E35: 10-14 | F35: A-B | G35: 19.32 | H35: 13.79 | I35: 18.47 | J35: =AVERAGE(G35:I35) -> 17.193333 | K35: 46091 | L35: 73.158 | M35: 46190 | N35: 99.02 | O35: 46 | P35: 69.5 | Q35: 78.5 | R35: 0.107 | S35: =M35-K35 -> 99 | T35: 13.985 | U35: 32.5 | AB35: 94.75 | AC35: 94 | AD35: 8 | AE35: 44.5 | AF35: 61.62 | AG35: 82.87 | AH35: 34.75 | AI35: √ | AJ35: √ | AL35: 34 | AM35: 40 | AN35: Plastik,Tatal,Benang | AO35: 347 | AP35: =AO35*35 -> 12145 | AQ35: =AP35/1260 -> 9.6388889 | AR35: 2 | AS35: =AR35*35 -> 70 | AT35: =AS35/1260 -> 0.055555556 | AU35: =AO35+AR35 -> 349 | AV35: =AP35+AS35 -> 12215 | AW35: =AQ35+AT35 -> 9.6944444 | AX35: 132 | AY35: - | AZ35: 141 | BA35: SIR 20
A36: 7 | B36: 35 | C36: 46191 | D36: 2 | E36: 10-14 | F36: A-B | G36: 17.36 | H36: 15.52 | I36: 17.81 | J36: =AVERAGE(G36:I36) -> 16.896667 | K36: 46091 | L36: 73.158 | M36: 46191 | N36: 99.02 | O36: 46 | P36: 69.5 | Q36: 78.5 | R36: 0.107 | S36: =M36-K36 -> 100 | T36: 12.55 | U36: 32.33 | AB36: 100 | AC36: 100.87 | AD36: 8 | AE36: 44.95 | AF36: 62.96 | AG36: 83.71 | AH36: 35.5 | AI36: √ | AJ36: √ | AL36: 34.36 | AM36: 55 | AN36: Plastik,Tatal,Tali | AO36: 345 | AP36: =AO36*35 -> 12075 | AQ36: =AP36/1260 -> 9.5833333 | AR36: 6 | AS36: =AR36*35 -> 210 | AT36: =AS36/1260 -> 0.16666667 | AU36: =AO36+AR36 -> 351 | AV36: =AP36+AS36 -> 12285 | AW36: =AQ36+AT36 -> 9.75 | AX36: 141 | AY36: - | AZ36: 151 | BA36: SIR 20
A37: 7 | B37: 36 | C37: 46192 | AB37: 95 | AC37: 95 | AD37: 8 | AE37: 43.75 | AF37: 65.3 | AG37: 83.2 | AH37: 34 | AI37: √ | AJ37: √ | AL37: 33.75 | AM37: 20 | AN37: Tatal,Plastik,Benang | AO37: 196 | AP37: =AO37*35 -> 6860 | AQ37: =AP37/1260 -> 5.4444444 | AR37: 6 | AS37: =AR37*35 -> 210 | AT37: =AS37/1260 -> 0.16666667 | AU37: =AO37+AR37 -> 202 | AV37: =AP37+AS37 -> 7070 | AW37: =AQ37+AT37 -> 5.6111111 | AX37: 151 | AY37: - | AZ37: 156 | BA37: SIR 20
A38: 7 | B38: 37 | C38: 46193 | AI38: √ | AJ38: √ | AL38: 33.5 | AM38: 10 | AN38: Kayu,Tali,Plastik | AO38: 86 | AP38: =AO38*35 -> 3010 | AQ38: =AP38/1260 -> 2.3888889 | AR38: 0 | AS38: =AR38*35 -> 0 | AT38: =AS38/1260 -> 0 | AU38: =AO38+AR38 -> 86 | AV38: =AP38+AS38 -> 3010 | AW38: =AQ38+AT38 -> 2.3888889 | AX38: 156 | AY38: - | AZ38: 158 | BA38: SIR 20
A39: 1 | B39: 38 | C39: 46213 | D39: 1 | E39: 1 | F39: A-C | K39: 46042 | L39: 67.91 | M39: 46213 | N39: 98.96 | O39: 35 | P39: 63.5 | Q39: 70.3 | S39: =M39-K39 -> 171 | T39: 20.75 | U39: 34.3 | AB39: 103 | AC39: 66.6 | AD39: 8 | AI39: P | AJ39: P | AK39: O | AP39: =AO39*35 -> 0 | AQ39: =AP39/1260 -> 0 | AS39: =AR39*35 -> 0 | AT39: =AS39/1260 -> 0 | AU39: =AO39+AR39 -> 0 | AV39: =AP39+AS39 -> 0 | AW39: =AQ39+AT39 -> 0 | AY39: - | BA39: SIR 20
A40: 1 | B40: 39 | C40: 46214 | K40: 46042 | L40: 67.91 | M40: 46214 | N40: 98.96 | O40: 35 | P40: 63.5 | Q40: 70.3 | S40: =M40-K40 -> 172 | AB40: 105 | AC40: 113 | AD40: 8 | AE40: 39 | AF40: 72 | AG40: 73.5 | AH40: 47 | AI40: P | AJ40: P | AK40: O | AL40: 38 | AM40: 1.91 | AN40: plastik, benang | AO40: 122 | AP40: =AO40*35 -> 4270 | AQ40: =AP40/1260 -> 3.3888889 | AR40: 13 | AS40: =AR40*35 -> 455 | AT40: =AS40/1260 -> 0.36111111 | AU40: =AO40+AR40 -> 135 | AV40: =AP40+AS40 -> 4725 | AW40: =AQ40+AT40 -> 3.75 | AX40: 159 | AY40: - | AZ40: 162 | BA40: SIR 20
...

Sheet Ctt_No. Reject
A1: CATATAN PRODUK YANG TIDAK SESUAI - Gabungan (FRM.OQC.05.01.00) | Divisi: Quality Control
A2: No | B2: Tanggal | C2: Batch | D2: Nomor Lot | E2: Nomor Produksi | F2: Jenis/SIR | G2: Faktor Ketidaksesuaian | H2: Kategori | I2: Nomor Corrective Action | J2: Berat (Kg) | K2: Jumlah Bale | L2: Keterangan | M2: Foto Sumber | N2: Catatan Transkripsi
A3: 1 | B3: 46149 | C3: 27 | E3: 004 | F3: SIR 20 | G3: Kontaminasi Cat | H3: Kontaminasi | I3: LKS 01 DRY | J3: 35 | K3: 1 | M3: 4
A4: 2 | B4: 46150 | C4: 28 | E4: 002 | F4: SIR 20 | G4: Metal Serbuk | H4: Metal Serbuk | I4: LKS 02 DRY | J4: 210 | K4: 6 | M4: 4 | N4: Tulisan bale tertimpa (terbaca 8/6); disesuaikan 210kg=6 bale
A5: 3 | B5: 46150 | C5: 28 | E5: 003 | F5: SIR 20 | G5: Metal Padat | H5: Metal Padat | I5: LKS 02 DRY | J5: 35 | K5: 1 | M5: 4
A6: 4 | B6: 46153 | C6: 28 | E6: 002 | F6: SIR 20 | G6: Metal Serbuk | H6: Metal Serbuk | I6: LKS 03 DRY | J6: 105 | K6: 3 | M6: 4
A7: 5 | B7: 46153 | C7: 28 | E7: 003 | F7: SIR 20 | G7: Metal Padat | H7: Metal Padat | I7: LKS 03 DRY | J7: 70 | K7: 1 | M7: 4 | N7: Ditulis 1B (70kg biasanya 2 bale)
A8: 6 | B8: 46157 | C8: 28 | E8: 004 | F8: SIR 20 | G8: Kontaminasi | H8: Kontaminasi | I8: LKS 04 DRY | J8: 35 | K8: 1 | M8: 4
A9: 7 | B9: 46157 | C9: 28 | E9: 002 | F9: SIR 20 | G9: Metal Serbuk | H9: Metal Serbuk | I9: LKS 04 DRY | J9: 105 | K9: 3 | M9: 4
A10: 8 | B10: 46157 | C10: 28 | E10: 003 | F10: SIR 20 | G10: Metal Padat | H10: Metal Padat | I10: LKS 04 DRY | J10: 35 | K10: 1 | M10: 4
A11: 9 | B11: 46161 | C11: 28 | E11: 002 | F11: SIR 20 | G11: Metal Serbuk | H11: Metal Serbuk | I11: LKS 05 DRY | J11: 35 | K11: 1 | M11: 4
A12: 10 | B12: 46161 | C12: 28 | E12: 003 | F12: SIR 20 | G12: Metal Padat | H12: Metal Padat | I12: LKS 05 DRY | J12: 35 | K12: 1 | M12: 4
A13: 11 | B13: 46161 | C13: 28 | E13: 001 | F13: SIR 20 | G13: Biskuit (Berjamur) | H13: Biskuit / Jamur | I13: LKS 05 DRY | J13: 1365 | K13: 39 | M13: 4
A14: 12 | B14: 46162 | C14: 28 | E14: 002 | F14: SIR 20 | G14: Metal Serbuk | H14: Metal Serbuk | I14: LKS 06 DRY | J14: 175 | K14: 5 | M14: 4
A15: 13 | B15: 46162 | C15: 28 | E15: 003 | F15: SIR 20 | G15: Metal Padat | H15: Metal Padat | I15: LKS 06 DRY | J15: 35 | K15: 1 | M15: 4
A16: 14 | B16: 46163 | C16: 28 | E16: 004 | F16: SIR 20 | G16: Kontaminasi | H16: Kontaminasi | I16: LKS 07 DRY | J16: 35 | K16: 1 | M16: 4
A17: 15 | B17: 46163 | C17: 28 | E17: 003 | F17: SIR 20 | G17: Metal Padat | H17: Metal Padat | I17: LKS 07 DRY | J17: 70 | K17: 2 | M17: 4
A18: 16 | B18: 46163 | C18: 28 | E18: 002 | F18: SIR 20 | G18: Metal Serbuk | H18: Metal Serbuk | I18: LKS 07 DRY | J18: 140 | K18: 4 | M18: 4
A19: 17 | B19: 46163 | C19: 4 | E19: 002 | F19: SIR 20 | G19: Metal Serbuk | H19: Metal Serbuk | I19: LKS 07 DRY | J19: 70 | K19: 2 | M19: 4
A20: 18 | B20: 46164 | C20: 4 | E20: 002 | F20: SIR 20 | G20: Metal Serbuk | H20: Metal Serbuk | I20: LKS 08 DRY | J20: 140 | K20: 4 | M20: 4 | N20: Nomor LKS terbaca '00', diasumsikan 08
A21: 19 | B21: 46165 | C21: 4 | E21: 003 | F21: SIR 20 | G21: Metal Padat | H21: Metal Padat | I21: LKS 09 DRY | J21: 35 | K21: 1 | M21: 4
